{"event": "RequestException encountered.", "exception": "Traceback (most recent call last):\n  File \"/home/amelieastbom/tdmenvs/tdmenv/lib/python3.7/site-packages/urllib3/connection.py\", line 159, in _new_conn\n    (self._dns_host, self.port), self.timeout, **extra_kw)\n  File \"/home/amelieastbom/tdmenvs/tdmenv/lib/python3.7/site-packages/urllib3/util/connection.py\", line 80, in create_connection\n    raise err\n  File \"/home/amelieastbom/tdmenvs/tdmenv/lib/python3.7/site-packages/urllib3/util/connection.py\", line 70, in create_connection\n    sock.connect(sa)\nConnectionRefusedError: [Errno 111] Connection refused\n\nDuring handling of the above exception, another exception occurred:\n\nTraceback (most recent call last):\n  File \"/home/amelieastbom/tdmenvs/tdmenv/lib/python3.7/site-packages/urllib3/connectionpool.py\", line 600, in urlopen\n    chunked=chunked)\n  File \"/home/amelieastbom/tdmenvs/tdmenv/lib/python3.7/site-packages/urllib3/connectionpool.py\", line 354, in _make_request\n    conn.request(method, url, **httplib_request_kw)\n  File \"/usr/lib/python3.7/http/client.py\", line 1277, in request\n    self._send_request(method, url, body, headers, encode_chunked)\n  File \"/usr/lib/python3.7/http/client.py\", line 1323, in _send_request\n    self.endheaders(body, encode_chunked=encode_chunked)\n  File \"/usr/lib/python3.7/http/client.py\", line 1272, in endheaders\n    self._send_output(message_body, encode_chunked=encode_chunked)\n  File \"/usr/lib/python3.7/http/client.py\", line 1032, in _send_output\n    self.send(msg)\n  File \"/usr/lib/python3.7/http/client.py\", line 972, in send\n    self.connect()\n  File \"/home/amelieastbom/tdmenvs/tdmenv/lib/python3.7/site-packages/urllib3/connection.py\", line 181, in connect\n    conn = self._new_conn()\n  File \"/home/amelieastbom/tdmenvs/tdmenv/lib/python3.7/site-packages/urllib3/connection.py\", line 168, in _new_conn\n    self, \"Failed to establish a new connection: %s\" % e)\nurllib3.exceptions.NewConnectionError: <urllib3.connection.HTTPConnection object at 0x7f50ca7b3690>: Failed to establish a new connection: [Errno 111] Connection refused\n\nDuring handling of the above exception, another exception occurred:\n\nTraceback (most recent call last):\n  File \"/home/amelieastbom/tdmenvs/tdmenv/lib/python3.7/site-packages/requests/adapters.py\", line 449, in send\n    timeout=timeout\n  File \"/home/amelieastbom/tdmenvs/tdmenv/lib/python3.7/site-packages/urllib3/connectionpool.py\", line 638, in urlopen\n    _stacktrace=sys.exc_info()[2])\n  File \"/home/amelieastbom/tdmenvs/tdmenv/lib/python3.7/site-packages/urllib3/util/retry.py\", line 399, in increment\n    raise MaxRetryError(_pool, url, error or ResponseError(cause))\nurllib3.exceptions.MaxRetryError: HTTPConnectionPool(host='127.0.0.1', port=10100): Max retries exceeded with url: /current_time (Caused by NewConnectionError('<urllib3.connection.HTTPConnection object at 0x7f50ca7b3690>: Failed to establish a new connection: [Errno 111] Connection refused'))\n\nDuring handling of the above exception, another exception occurred:\n\nTraceback (most recent call last):\n  File \"/home/amelieastbom/tdm-master/tdm/tdm/ddd/services/http.py\", line 33, in _post\n    response = requests.post(self._endpoint, data=data, headers=headers, timeout=2)\n  File \"/home/amelieastbom/tdmenvs/tdmenv/lib/python3.7/site-packages/requests/api.py\", line 116, in post\n    return request('post', url, data=data, json=json, **kwargs)\n  File \"/home/amelieastbom/tdmenvs/tdmenv/lib/python3.7/site-packages/requests/api.py\", line 60, in request\n    return session.request(method=method, url=url, **kwargs)\n  File \"/home/amelieastbom/tdmenvs/tdmenv/lib/python3.7/site-packages/requests/sessions.py\", line 533, in request\n    resp = self.send(prep, **send_kwargs)\n  File \"/home/amelieastbom/tdmenvs/tdmenv/lib/python3.7/site-packages/requests/sessions.py\", line 646, in send\n    r = adapter.send(request, **kwargs)\n  File \"/home/amelieastbom/tdmenvs/tdmenv/lib/python3.7/site-packages/requests/adapters.py\", line 516, in send\n    raise ConnectionError(e, request=request)\nrequests.exceptions.ConnectionError: HTTPConnectionPool(host='127.0.0.1', port=10100): Max retries exceeded with url: /current_time (Caused by NewConnectionError('<urllib3.connection.HTTPConnection object at 0x7f50ca7b3690>: Failed to establish a new connection: [Errno 111] Connection refused'))", "level": "error", "logger": "tdm", "time": "2020-09-17T13:51:30.736966Z"}
{"event": "Encountered an error. Stopping and returning backend error.", "exception": "Traceback (most recent call last):\n  File \"/home/amelieastbom/tdmenvs/tdmenv/lib/python3.7/site-packages/urllib3/connection.py\", line 159, in _new_conn\n    (self._dns_host, self.port), self.timeout, **extra_kw)\n  File \"/home/amelieastbom/tdmenvs/tdmenv/lib/python3.7/site-packages/urllib3/util/connection.py\", line 80, in create_connection\n    raise err\n  File \"/home/amelieastbom/tdmenvs/tdmenv/lib/python3.7/site-packages/urllib3/util/connection.py\", line 70, in create_connection\n    sock.connect(sa)\nConnectionRefusedError: [Errno 111] Connection refused\n\nDuring handling of the above exception, another exception occurred:\n\nTraceback (most recent call last):\n  File \"/home/amelieastbom/tdmenvs/tdmenv/lib/python3.7/site-packages/urllib3/connectionpool.py\", line 600, in urlopen\n    chunked=chunked)\n  File \"/home/amelieastbom/tdmenvs/tdmenv/lib/python3.7/site-packages/urllib3/connectionpool.py\", line 354, in _make_request\n    conn.request(method, url, **httplib_request_kw)\n  File \"/usr/lib/python3.7/http/client.py\", line 1277, in request\n    self._send_request(method, url, body, headers, encode_chunked)\n  File \"/usr/lib/python3.7/http/client.py\", line 1323, in _send_request\n    self.endheaders(body, encode_chunked=encode_chunked)\n  File \"/usr/lib/python3.7/http/client.py\", line 1272, in endheaders\n    self._send_output(message_body, encode_chunked=encode_chunked)\n  File \"/usr/lib/python3.7/http/client.py\", line 1032, in _send_output\n    self.send(msg)\n  File \"/usr/lib/python3.7/http/client.py\", line 972, in send\n    self.connect()\n  File \"/home/amelieastbom/tdmenvs/tdmenv/lib/python3.7/site-packages/urllib3/connection.py\", line 181, in connect\n    conn = self._new_conn()\n  File \"/home/amelieastbom/tdmenvs/tdmenv/lib/python3.7/site-packages/urllib3/connection.py\", line 168, in _new_conn\n    self, \"Failed to establish a new connection: %s\" % e)\nurllib3.exceptions.NewConnectionError: <urllib3.connection.HTTPConnection object at 0x7f50ca7b3690>: Failed to establish a new connection: [Errno 111] Connection refused\n\nDuring handling of the above exception, another exception occurred:\n\nTraceback (most recent call last):\n  File \"/home/amelieastbom/tdmenvs/tdmenv/lib/python3.7/site-packages/requests/adapters.py\", line 449, in send\n    timeout=timeout\n  File \"/home/amelieastbom/tdmenvs/tdmenv/lib/python3.7/site-packages/urllib3/connectionpool.py\", line 638, in urlopen\n    _stacktrace=sys.exc_info()[2])\n  File \"/home/amelieastbom/tdmenvs/tdmenv/lib/python3.7/site-packages/urllib3/util/retry.py\", line 399, in increment\n    raise MaxRetryError(_pool, url, error or ResponseError(cause))\nurllib3.exceptions.MaxRetryError: HTTPConnectionPool(host='127.0.0.1', port=10100): Max retries exceeded with url: /current_time (Caused by NewConnectionError('<urllib3.connection.HTTPConnection object at 0x7f50ca7b3690>: Failed to establish a new connection: [Errno 111] Connection refused'))\n\nDuring handling of the above exception, another exception occurred:\n\nTraceback (most recent call last):\n  File \"/home/amelieastbom/tdm-master/tdm/tdm/ddd/services/http.py\", line 33, in _post\n    response = requests.post(self._endpoint, data=data, headers=headers, timeout=2)\n  File \"/home/amelieastbom/tdmenvs/tdmenv/lib/python3.7/site-packages/requests/api.py\", line 116, in post\n    return request('post', url, data=data, json=json, **kwargs)\n  File \"/home/amelieastbom/tdmenvs/tdmenv/lib/python3.7/site-packages/requests/api.py\", line 60, in request\n    return session.request(method=method, url=url, **kwargs)\n  File \"/home/amelieastbom/tdmenvs/tdmenv/lib/python3.7/site-packages/requests/sessions.py\", line 533, in request\n    resp = self.send(prep, **send_kwargs)\n  File \"/home/amelieastbom/tdmenvs/tdmenv/lib/python3.7/site-packages/requests/sessions.py\", line 646, in send\n    r = adapter.send(request, **kwargs)\n  File \"/home/amelieastbom/tdmenvs/tdmenv/lib/python3.7/site-packages/requests/adapters.py\", line 516, in send\n    raise ConnectionError(e, request=request)\nrequests.exceptions.ConnectionError: HTTPConnectionPool(host='127.0.0.1', port=10100): Max retries exceeded with url: /current_time (Caused by NewConnectionError('<urllib3.connection.HTTPConnection object at 0x7f50ca7b3690>: Failed to establish a new connection: [Errno 111] Connection refused'))\n\nDuring handling of the above exception, another exception occurred:\n\nTraceback (most recent call last):\n  File \"/home/amelieastbom/tdm-master/tdm/tdm/backend/backend.py\", line 89, in handle_request_from_queue\n    self._handle_request(request)\n  File \"/home/amelieastbom/tdm-master/tdm/tdm/backend/backend.py\", line 115, in _handle_request\n    self._send_event_through_components_and_set_response(event)\n  File \"/home/amelieastbom/tdm-master/tdm/tdm/backend/backend.py\", line 321, in _send_event_through_components_and_set_response\n    resulting_events = self._send_event_through_components(event)\n  File \"/home/amelieastbom/tdm-master/tdm/tdm/backend/backend.py\", line 334, in _send_event_through_components\n    moves = self._dm.act(events)\n  File \"/home/amelieastbom/tdm-master/tdm/tdm/dm/component.py\", line 46, in act\n    self._act_on_queued_events()\n  File \"/home/amelieastbom/tdm-master/tdm/tdm/dm/component.py\", line 86, in _act_on_queued_events\n    self._handle_event(event)\n  File \"/home/amelieastbom/tdm-master/tdm/tdm/dm/component.py\", line 101, in _handle_event\n    self.forward_event_internally_and_externally(event)\n  File \"/home/amelieastbom/tdm-master/tdm/tdm/dm/component.py\", line 104, in forward_event_internally_and_externally\n    self._event_dispatcher.dispatch(event)\n  File \"/home/amelieastbom/tdm-master/tdm/tdm/event_dispatcher.py\", line 27, in dispatch\n    self._send_event_to_subscribing_modules(event)\n  File \"/home/amelieastbom/tdm-master/tdm/tdm/event_dispatcher.py\", line 49, in _send_event_to_subscribing_modules\n    handler, event.get_type(), event)\n  File \"/home/amelieastbom/tdm-master/tdm/tdm/event_dispatcher.py\", line 55, in _send_to_subscribing_module\n    module.process_event(protected_event)\n  File \"/home/amelieastbom/tdm-master/tdm/tdm/dm/module.py\", line 50, in process_event\n    handler()\n  File \"/home/amelieastbom/tdm-master/tdm/tdm/dm/dme_module.py\", line 66, in _handle_interpretation\n    self._set_input_event_and_run_update_and_select()\n  File \"/home/amelieastbom/tdm-master/tdm/tdm/dm/dme_module.py\", line 71, in _set_input_event_and_run_update_and_select\n    self.run_update_and_set_ddd_when_needed()\n  File \"/home/amelieastbom/tdm-master/tdm/tdm/dm/dme_module.py\", line 76, in run_update_and_set_ddd_when_needed\n    self.run_update()\n  File \"/home/amelieastbom/tdm-master/tdm/tdm/dm/dme_module.py\", line 138, in run_update\n    self.update_module.run(self._tis)\n  File \"/home/amelieastbom/tdm-master/tdm/tdm/dm/update.py\", line 274, in run\n    RuleGroup.repeat_group_sequence(self.logger, [self._exec_plan_group, self._load_plan_group], tis)\n  File \"/home/amelieastbom/tdm-master/tdm/tdm/dm/isu_rule_group.py\", line 58, in repeat_group_sequence\n    group.apply_first_applicable_rule(tis)\n  File \"/home/amelieastbom/tdm-master/tdm/tdm/dm/isu_rule_group.py\", line 19, in apply_first_applicable_rule\n    rule.apply(tis)\n  File \"/home/amelieastbom/tdm-master/tdm/tdm/dm/isu_rule.py\", line 35, in apply\n    self.apply_effects(self._ddd_component_manager, tis)\n  File \"/home/amelieastbom/tdm-master/tdm/tdm/dm/isu_rule.py\", line 45, in apply_effects\n    self.effects(ddd_component_manager, tis, *self.vars)\n  File \"/home/amelieastbom/tdm-master/tdm/tdm/dm/update_rules.py\", line 1813, in effects\n    results = tis.invoke_service_query(question, min_results=1, max_results=1)\n  File \"/home/amelieastbom/tdm-master/tdm/tdm/dm/tis.py\", line 670, in invoke_service_query\n    question, self.session_id, facts, self.language_code, max_results=max_results, min_results=min_results)\n  File \"/home/amelieastbom/tdm-master/tdm/tdm/dm/service_manager.py\", line 202, in query\n    results = get_query_results_for_interface(ddd, interface)\n  File \"/home/amelieastbom/tdm-master/tdm/tdm/dm/service_manager.py\", line 185, in get_query_results_for_interface\n    return service_wrapper.query(question, parameters, min_results, max_results, session, context)\n  File \"/home/amelieastbom/tdm-master/tdm/tdm/ddd/services/http.py\", line 159, in query\n    headers={\"Content-type\": \"application/json\"})\n  File \"/home/amelieastbom/tdm-master/tdm/tdm/ddd/services/http.py\", line 38, in _post\n    raise HttpServiceInvocationException(str(exception))\ntdm.ddd.services.http.HttpServiceInvocationException: HTTPConnectionPool(host='127.0.0.1', port=10100): Max retries exceeded with url: /current_time (Caused by NewConnectionError('<urllib3.connection.HTTPConnection object at 0x7f50ca7b3690>: Failed to establish a new connection: [Errno 111] Connection refused'))", "level": "error", "logger": "tdm", "time": "2020-09-17T13:51:30.743910Z"}
{"event": "RequestException encountered.", "exception": "Traceback (most recent call last):\n  File \"/home/amelieastbom/tdmenvs/tdmenv/lib/python3.7/site-packages/urllib3/connection.py\", line 159, in _new_conn\n    (self._dns_host, self.port), self.timeout, **extra_kw)\n  File \"/home/amelieastbom/tdmenvs/tdmenv/lib/python3.7/site-packages/urllib3/util/connection.py\", line 80, in create_connection\n    raise err\n  File \"/home/amelieastbom/tdmenvs/tdmenv/lib/python3.7/site-packages/urllib3/util/connection.py\", line 70, in create_connection\n    sock.connect(sa)\nConnectionRefusedError: [Errno 111] Connection refused\n\nDuring handling of the above exception, another exception occurred:\n\nTraceback (most recent call last):\n  File \"/home/amelieastbom/tdmenvs/tdmenv/lib/python3.7/site-packages/urllib3/connectionpool.py\", line 600, in urlopen\n    chunked=chunked)\n  File \"/home/amelieastbom/tdmenvs/tdmenv/lib/python3.7/site-packages/urllib3/connectionpool.py\", line 354, in _make_request\n    conn.request(method, url, **httplib_request_kw)\n  File \"/usr/lib/python3.7/http/client.py\", line 1277, in request\n    self._send_request(method, url, body, headers, encode_chunked)\n  File \"/usr/lib/python3.7/http/client.py\", line 1323, in _send_request\n    self.endheaders(body, encode_chunked=encode_chunked)\n  File \"/usr/lib/python3.7/http/client.py\", line 1272, in endheaders\n    self._send_output(message_body, encode_chunked=encode_chunked)\n  File \"/usr/lib/python3.7/http/client.py\", line 1032, in _send_output\n    self.send(msg)\n  File \"/usr/lib/python3.7/http/client.py\", line 972, in send\n    self.connect()\n  File \"/home/amelieastbom/tdmenvs/tdmenv/lib/python3.7/site-packages/urllib3/connection.py\", line 181, in connect\n    conn = self._new_conn()\n  File \"/home/amelieastbom/tdmenvs/tdmenv/lib/python3.7/site-packages/urllib3/connection.py\", line 168, in _new_conn\n    self, \"Failed to establish a new connection: %s\" % e)\nurllib3.exceptions.NewConnectionError: <urllib3.connection.HTTPConnection object at 0x7f50ca46a2d0>: Failed to establish a new connection: [Errno 111] Connection refused\n\nDuring handling of the above exception, another exception occurred:\n\nTraceback (most recent call last):\n  File \"/home/amelieastbom/tdmenvs/tdmenv/lib/python3.7/site-packages/requests/adapters.py\", line 449, in send\n    timeout=timeout\n  File \"/home/amelieastbom/tdmenvs/tdmenv/lib/python3.7/site-packages/urllib3/connectionpool.py\", line 638, in urlopen\n    _stacktrace=sys.exc_info()[2])\n  File \"/home/amelieastbom/tdmenvs/tdmenv/lib/python3.7/site-packages/urllib3/util/retry.py\", line 399, in increment\n    raise MaxRetryError(_pool, url, error or ResponseError(cause))\nurllib3.exceptions.MaxRetryError: HTTPConnectionPool(host='127.0.0.1', port=10100): Max retries exceeded with url: /set_time (Caused by NewConnectionError('<urllib3.connection.HTTPConnection object at 0x7f50ca46a2d0>: Failed to establish a new connection: [Errno 111] Connection refused'))\n\nDuring handling of the above exception, another exception occurred:\n\nTraceback (most recent call last):\n  File \"/home/amelieastbom/tdm-master/tdm/tdm/ddd/services/http.py\", line 33, in _post\n    response = requests.post(self._endpoint, data=data, headers=headers, timeout=2)\n  File \"/home/amelieastbom/tdmenvs/tdmenv/lib/python3.7/site-packages/requests/api.py\", line 116, in post\n    return request('post', url, data=data, json=json, **kwargs)\n  File \"/home/amelieastbom/tdmenvs/tdmenv/lib/python3.7/site-packages/requests/api.py\", line 60, in request\n    return session.request(method=method, url=url, **kwargs)\n  File \"/home/amelieastbom/tdmenvs/tdmenv/lib/python3.7/site-packages/requests/sessions.py\", line 533, in request\n    resp = self.send(prep, **send_kwargs)\n  File \"/home/amelieastbom/tdmenvs/tdmenv/lib/python3.7/site-packages/requests/sessions.py\", line 646, in send\n    r = adapter.send(request, **kwargs)\n  File \"/home/amelieastbom/tdmenvs/tdmenv/lib/python3.7/site-packages/requests/adapters.py\", line 516, in send\n    raise ConnectionError(e, request=request)\nrequests.exceptions.ConnectionError: HTTPConnectionPool(host='127.0.0.1', port=10100): Max retries exceeded with url: /set_time (Caused by NewConnectionError('<urllib3.connection.HTTPConnection object at 0x7f50ca46a2d0>: Failed to establish a new connection: [Errno 111] Connection refused'))", "level": "error", "logger": "tdm", "time": "2020-09-17T13:51:30.932798Z"}
{"event": "Encountered an error. Stopping and returning backend error.", "exception": "Traceback (most recent call last):\n  File \"/home/amelieastbom/tdmenvs/tdmenv/lib/python3.7/site-packages/urllib3/connection.py\", line 159, in _new_conn\n    (self._dns_host, self.port), self.timeout, **extra_kw)\n  File \"/home/amelieastbom/tdmenvs/tdmenv/lib/python3.7/site-packages/urllib3/util/connection.py\", line 80, in create_connection\n    raise err\n  File \"/home/amelieastbom/tdmenvs/tdmenv/lib/python3.7/site-packages/urllib3/util/connection.py\", line 70, in create_connection\n    sock.connect(sa)\nConnectionRefusedError: [Errno 111] Connection refused\n\nDuring handling of the above exception, another exception occurred:\n\nTraceback (most recent call last):\n  File \"/home/amelieastbom/tdmenvs/tdmenv/lib/python3.7/site-packages/urllib3/connectionpool.py\", line 600, in urlopen\n    chunked=chunked)\n  File \"/home/amelieastbom/tdmenvs/tdmenv/lib/python3.7/site-packages/urllib3/connectionpool.py\", line 354, in _make_request\n    conn.request(method, url, **httplib_request_kw)\n  File \"/usr/lib/python3.7/http/client.py\", line 1277, in request\n    self._send_request(method, url, body, headers, encode_chunked)\n  File \"/usr/lib/python3.7/http/client.py\", line 1323, in _send_request\n    self.endheaders(body, encode_chunked=encode_chunked)\n  File \"/usr/lib/python3.7/http/client.py\", line 1272, in endheaders\n    self._send_output(message_body, encode_chunked=encode_chunked)\n  File \"/usr/lib/python3.7/http/client.py\", line 1032, in _send_output\n    self.send(msg)\n  File \"/usr/lib/python3.7/http/client.py\", line 972, in send\n    self.connect()\n  File \"/home/amelieastbom/tdmenvs/tdmenv/lib/python3.7/site-packages/urllib3/connection.py\", line 181, in connect\n    conn = self._new_conn()\n  File \"/home/amelieastbom/tdmenvs/tdmenv/lib/python3.7/site-packages/urllib3/connection.py\", line 168, in _new_conn\n    self, \"Failed to establish a new connection: %s\" % e)\nurllib3.exceptions.NewConnectionError: <urllib3.connection.HTTPConnection object at 0x7f50ca46a2d0>: Failed to establish a new connection: [Errno 111] Connection refused\n\nDuring handling of the above exception, another exception occurred:\n\nTraceback (most recent call last):\n  File \"/home/amelieastbom/tdmenvs/tdmenv/lib/python3.7/site-packages/requests/adapters.py\", line 449, in send\n    timeout=timeout\n  File \"/home/amelieastbom/tdmenvs/tdmenv/lib/python3.7/site-packages/urllib3/connectionpool.py\", line 638, in urlopen\n    _stacktrace=sys.exc_info()[2])\n  File \"/home/amelieastbom/tdmenvs/tdmenv/lib/python3.7/site-packages/urllib3/util/retry.py\", line 399, in increment\n    raise MaxRetryError(_pool, url, error or ResponseError(cause))\nurllib3.exceptions.MaxRetryError: HTTPConnectionPool(host='127.0.0.1', port=10100): Max retries exceeded with url: /set_time (Caused by NewConnectionError('<urllib3.connection.HTTPConnection object at 0x7f50ca46a2d0>: Failed to establish a new connection: [Errno 111] Connection refused'))\n\nDuring handling of the above exception, another exception occurred:\n\nTraceback (most recent call last):\n  File \"/home/amelieastbom/tdm-master/tdm/tdm/ddd/services/http.py\", line 33, in _post\n    response = requests.post(self._endpoint, data=data, headers=headers, timeout=2)\n  File \"/home/amelieastbom/tdmenvs/tdmenv/lib/python3.7/site-packages/requests/api.py\", line 116, in post\n    return request('post', url, data=data, json=json, **kwargs)\n  File \"/home/amelieastbom/tdmenvs/tdmenv/lib/python3.7/site-packages/requests/api.py\", line 60, in request\n    return session.request(method=method, url=url, **kwargs)\n  File \"/home/amelieastbom/tdmenvs/tdmenv/lib/python3.7/site-packages/requests/sessions.py\", line 533, in request\n    resp = self.send(prep, **send_kwargs)\n  File \"/home/amelieastbom/tdmenvs/tdmenv/lib/python3.7/site-packages/requests/sessions.py\", line 646, in send\n    r = adapter.send(request, **kwargs)\n  File \"/home/amelieastbom/tdmenvs/tdmenv/lib/python3.7/site-packages/requests/adapters.py\", line 516, in send\n    raise ConnectionError(e, request=request)\nrequests.exceptions.ConnectionError: HTTPConnectionPool(host='127.0.0.1', port=10100): Max retries exceeded with url: /set_time (Caused by NewConnectionError('<urllib3.connection.HTTPConnection object at 0x7f50ca46a2d0>: Failed to establish a new connection: [Errno 111] Connection refused'))\n\nDuring handling of the above exception, another exception occurred:\n\nTraceback (most recent call last):\n  File \"/home/amelieastbom/tdm-master/tdm/tdm/backend/backend.py\", line 89, in handle_request_from_queue\n    self._handle_request(request)\n  File \"/home/amelieastbom/tdm-master/tdm/tdm/backend/backend.py\", line 115, in _handle_request\n    self._send_event_through_components_and_set_response(event)\n  File \"/home/amelieastbom/tdm-master/tdm/tdm/backend/backend.py\", line 321, in _send_event_through_components_and_set_response\n    resulting_events = self._send_event_through_components(event)\n  File \"/home/amelieastbom/tdm-master/tdm/tdm/backend/backend.py\", line 334, in _send_event_through_components\n    moves = self._dm.act(events)\n  File \"/home/amelieastbom/tdm-master/tdm/tdm/dm/component.py\", line 46, in act\n    self._act_on_queued_events()\n  File \"/home/amelieastbom/tdm-master/tdm/tdm/dm/component.py\", line 86, in _act_on_queued_events\n    self._handle_event(event)\n  File \"/home/amelieastbom/tdm-master/tdm/tdm/dm/component.py\", line 101, in _handle_event\n    self.forward_event_internally_and_externally(event)\n  File \"/home/amelieastbom/tdm-master/tdm/tdm/dm/component.py\", line 104, in forward_event_internally_and_externally\n    self._event_dispatcher.dispatch(event)\n  File \"/home/amelieastbom/tdm-master/tdm/tdm/event_dispatcher.py\", line 27, in dispatch\n    self._send_event_to_subscribing_modules(event)\n  File \"/home/amelieastbom/tdm-master/tdm/tdm/event_dispatcher.py\", line 49, in _send_event_to_subscribing_modules\n    handler, event.get_type(), event)\n  File \"/home/amelieastbom/tdm-master/tdm/tdm/event_dispatcher.py\", line 55, in _send_to_subscribing_module\n    module.process_event(protected_event)\n  File \"/home/amelieastbom/tdm-master/tdm/tdm/dm/module.py\", line 50, in process_event\n    handler()\n  File \"/home/amelieastbom/tdm-master/tdm/tdm/dm/dme_module.py\", line 66, in _handle_interpretation\n    self._set_input_event_and_run_update_and_select()\n  File \"/home/amelieastbom/tdm-master/tdm/tdm/dm/dme_module.py\", line 71, in _set_input_event_and_run_update_and_select\n    self.run_update_and_set_ddd_when_needed()\n  File \"/home/amelieastbom/tdm-master/tdm/tdm/dm/dme_module.py\", line 76, in run_update_and_set_ddd_when_needed\n    self.run_update()\n  File \"/home/amelieastbom/tdm-master/tdm/tdm/dm/dme_module.py\", line 138, in run_update\n    self.update_module.run(self._tis)\n  File \"/home/amelieastbom/tdm-master/tdm/tdm/dm/update.py\", line 274, in run\n    RuleGroup.repeat_group_sequence(self.logger, [self._exec_plan_group, self._load_plan_group], tis)\n  File \"/home/amelieastbom/tdm-master/tdm/tdm/dm/isu_rule_group.py\", line 58, in repeat_group_sequence\n    group.apply_first_applicable_rule(tis)\n  File \"/home/amelieastbom/tdm-master/tdm/tdm/dm/isu_rule_group.py\", line 19, in apply_first_applicable_rule\n    rule.apply(tis)\n  File \"/home/amelieastbom/tdm-master/tdm/tdm/dm/isu_rule.py\", line 35, in apply\n    self.apply_effects(self._ddd_component_manager, tis)\n  File \"/home/amelieastbom/tdm-master/tdm/tdm/dm/isu_rule.py\", line 45, in apply_effects\n    self.effects(ddd_component_manager, tis, *self.vars)\n  File \"/home/amelieastbom/tdm-master/tdm/tdm/dm/update_rules.py\", line 1890, in effects\n    self.perform_service_action()\n  File \"/home/amelieastbom/tdm-master/tdm/tdm/dm/update_rules.py\", line 1915, in perform_service_action\n    self.tis.session_id, self.facts, self.tis.language_code)\n  File \"/home/amelieastbom/tdm-master/tdm/tdm/dm/service_manager.py\", line 66, in perform\n    Context(ddd_name, facts, language_code, invocation_id))\n  File \"/home/amelieastbom/tdm-master/tdm/tdm/ddd/services/http.py\", line 135, in perform\n    headers={\"Content-type\": \"application/json\"})\n  File \"/home/amelieastbom/tdm-master/tdm/tdm/ddd/services/http.py\", line 38, in _post\n    raise HttpServiceInvocationException(str(exception))\ntdm.ddd.services.http.HttpServiceInvocationException: HTTPConnectionPool(host='127.0.0.1', port=10100): Max retries exceeded with url: /set_time (Caused by NewConnectionError('<urllib3.connection.HTTPConnection object at 0x7f50ca46a2d0>: Failed to establish a new connection: [Errno 111] Connection refused'))", "level": "error", "logger": "tdm", "time": "2020-09-17T13:51:30.933940Z"}
{"event": "RequestException encountered.", "exception": "Traceback (most recent call last):\n  File \"/home/amelieastbom/tdmenvs/tdmenv/lib/python3.7/site-packages/urllib3/connection.py\", line 159, in _new_conn\n    (self._dns_host, self.port), self.timeout, **extra_kw)\n  File \"/home/amelieastbom/tdmenvs/tdmenv/lib/python3.7/site-packages/urllib3/util/connection.py\", line 80, in create_connection\n    raise err\n  File \"/home/amelieastbom/tdmenvs/tdmenv/lib/python3.7/site-packages/urllib3/util/connection.py\", line 70, in create_connection\n    sock.connect(sa)\nConnectionRefusedError: [Errno 111] Connection refused\n\nDuring handling of the above exception, another exception occurred:\n\nTraceback (most recent call last):\n  File \"/home/amelieastbom/tdmenvs/tdmenv/lib/python3.7/site-packages/urllib3/connectionpool.py\", line 600, in urlopen\n    chunked=chunked)\n  File \"/home/amelieastbom/tdmenvs/tdmenv/lib/python3.7/site-packages/urllib3/connectionpool.py\", line 354, in _make_request\n    conn.request(method, url, **httplib_request_kw)\n  File \"/usr/lib/python3.7/http/client.py\", line 1277, in request\n    self._send_request(method, url, body, headers, encode_chunked)\n  File \"/usr/lib/python3.7/http/client.py\", line 1323, in _send_request\n    self.endheaders(body, encode_chunked=encode_chunked)\n  File \"/usr/lib/python3.7/http/client.py\", line 1272, in endheaders\n    self._send_output(message_body, encode_chunked=encode_chunked)\n  File \"/usr/lib/python3.7/http/client.py\", line 1032, in _send_output\n    self.send(msg)\n  File \"/usr/lib/python3.7/http/client.py\", line 972, in send\n    self.connect()\n  File \"/home/amelieastbom/tdmenvs/tdmenv/lib/python3.7/site-packages/urllib3/connection.py\", line 181, in connect\n    conn = self._new_conn()\n  File \"/home/amelieastbom/tdmenvs/tdmenv/lib/python3.7/site-packages/urllib3/connection.py\", line 168, in _new_conn\n    self, \"Failed to establish a new connection: %s\" % e)\nurllib3.exceptions.NewConnectionError: <urllib3.connection.HTTPConnection object at 0x7f50ca40ead0>: Failed to establish a new connection: [Errno 111] Connection refused\n\nDuring handling of the above exception, another exception occurred:\n\nTraceback (most recent call last):\n  File \"/home/amelieastbom/tdmenvs/tdmenv/lib/python3.7/site-packages/requests/adapters.py\", line 449, in send\n    timeout=timeout\n  File \"/home/amelieastbom/tdmenvs/tdmenv/lib/python3.7/site-packages/urllib3/connectionpool.py\", line 638, in urlopen\n    _stacktrace=sys.exc_info()[2])\n  File \"/home/amelieastbom/tdmenvs/tdmenv/lib/python3.7/site-packages/urllib3/util/retry.py\", line 399, in increment\n    raise MaxRetryError(_pool, url, error or ResponseError(cause))\nurllib3.exceptions.MaxRetryError: HTTPConnectionPool(host='127.0.0.1', port=10100): Max retries exceeded with url: /set_time (Caused by NewConnectionError('<urllib3.connection.HTTPConnection object at 0x7f50ca40ead0>: Failed to establish a new connection: [Errno 111] Connection refused'))\n\nDuring handling of the above exception, another exception occurred:\n\nTraceback (most recent call last):\n  File \"/home/amelieastbom/tdm-master/tdm/tdm/ddd/services/http.py\", line 33, in _post\n    response = requests.post(self._endpoint, data=data, headers=headers, timeout=2)\n  File \"/home/amelieastbom/tdmenvs/tdmenv/lib/python3.7/site-packages/requests/api.py\", line 116, in post\n    return request('post', url, data=data, json=json, **kwargs)\n  File \"/home/amelieastbom/tdmenvs/tdmenv/lib/python3.7/site-packages/requests/api.py\", line 60, in request\n    return session.request(method=method, url=url, **kwargs)\n  File \"/home/amelieastbom/tdmenvs/tdmenv/lib/python3.7/site-packages/requests/sessions.py\", line 533, in request\n    resp = self.send(prep, **send_kwargs)\n  File \"/home/amelieastbom/tdmenvs/tdmenv/lib/python3.7/site-packages/requests/sessions.py\", line 646, in send\n    r = adapter.send(request, **kwargs)\n  File \"/home/amelieastbom/tdmenvs/tdmenv/lib/python3.7/site-packages/requests/adapters.py\", line 516, in send\n    raise ConnectionError(e, request=request)\nrequests.exceptions.ConnectionError: HTTPConnectionPool(host='127.0.0.1', port=10100): Max retries exceeded with url: /set_time (Caused by NewConnectionError('<urllib3.connection.HTTPConnection object at 0x7f50ca40ead0>: Failed to establish a new connection: [Errno 111] Connection refused'))", "level": "error", "logger": "tdm", "time": "2020-09-17T13:51:31.102126Z"}
{"event": "Encountered an error. Stopping and returning backend error.", "exception": "Traceback (most recent call last):\n  File \"/home/amelieastbom/tdmenvs/tdmenv/lib/python3.7/site-packages/urllib3/connection.py\", line 159, in _new_conn\n    (self._dns_host, self.port), self.timeout, **extra_kw)\n  File \"/home/amelieastbom/tdmenvs/tdmenv/lib/python3.7/site-packages/urllib3/util/connection.py\", line 80, in create_connection\n    raise err\n  File \"/home/amelieastbom/tdmenvs/tdmenv/lib/python3.7/site-packages/urllib3/util/connection.py\", line 70, in create_connection\n    sock.connect(sa)\nConnectionRefusedError: [Errno 111] Connection refused\n\nDuring handling of the above exception, another exception occurred:\n\nTraceback (most recent call last):\n  File \"/home/amelieastbom/tdmenvs/tdmenv/lib/python3.7/site-packages/urllib3/connectionpool.py\", line 600, in urlopen\n    chunked=chunked)\n  File \"/home/amelieastbom/tdmenvs/tdmenv/lib/python3.7/site-packages/urllib3/connectionpool.py\", line 354, in _make_request\n    conn.request(method, url, **httplib_request_kw)\n  File \"/usr/lib/python3.7/http/client.py\", line 1277, in request\n    self._send_request(method, url, body, headers, encode_chunked)\n  File \"/usr/lib/python3.7/http/client.py\", line 1323, in _send_request\n    self.endheaders(body, encode_chunked=encode_chunked)\n  File \"/usr/lib/python3.7/http/client.py\", line 1272, in endheaders\n    self._send_output(message_body, encode_chunked=encode_chunked)\n  File \"/usr/lib/python3.7/http/client.py\", line 1032, in _send_output\n    self.send(msg)\n  File \"/usr/lib/python3.7/http/client.py\", line 972, in send\n    self.connect()\n  File \"/home/amelieastbom/tdmenvs/tdmenv/lib/python3.7/site-packages/urllib3/connection.py\", line 181, in connect\n    conn = self._new_conn()\n  File \"/home/amelieastbom/tdmenvs/tdmenv/lib/python3.7/site-packages/urllib3/connection.py\", line 168, in _new_conn\n    self, \"Failed to establish a new connection: %s\" % e)\nurllib3.exceptions.NewConnectionError: <urllib3.connection.HTTPConnection object at 0x7f50ca40ead0>: Failed to establish a new connection: [Errno 111] Connection refused\n\nDuring handling of the above exception, another exception occurred:\n\nTraceback (most recent call last):\n  File \"/home/amelieastbom/tdmenvs/tdmenv/lib/python3.7/site-packages/requests/adapters.py\", line 449, in send\n    timeout=timeout\n  File \"/home/amelieastbom/tdmenvs/tdmenv/lib/python3.7/site-packages/urllib3/connectionpool.py\", line 638, in urlopen\n    _stacktrace=sys.exc_info()[2])\n  File \"/home/amelieastbom/tdmenvs/tdmenv/lib/python3.7/site-packages/urllib3/util/retry.py\", line 399, in increment\n    raise MaxRetryError(_pool, url, error or ResponseError(cause))\nurllib3.exceptions.MaxRetryError: HTTPConnectionPool(host='127.0.0.1', port=10100): Max retries exceeded with url: /set_time (Caused by NewConnectionError('<urllib3.connection.HTTPConnection object at 0x7f50ca40ead0>: Failed to establish a new connection: [Errno 111] Connection refused'))\n\nDuring handling of the above exception, another exception occurred:\n\nTraceback (most recent call last):\n  File \"/home/amelieastbom/tdm-master/tdm/tdm/ddd/services/http.py\", line 33, in _post\n    response = requests.post(self._endpoint, data=data, headers=headers, timeout=2)\n  File \"/home/amelieastbom/tdmenvs/tdmenv/lib/python3.7/site-packages/requests/api.py\", line 116, in post\n    return request('post', url, data=data, json=json, **kwargs)\n  File \"/home/amelieastbom/tdmenvs/tdmenv/lib/python3.7/site-packages/requests/api.py\", line 60, in request\n    return session.request(method=method, url=url, **kwargs)\n  File \"/home/amelieastbom/tdmenvs/tdmenv/lib/python3.7/site-packages/requests/sessions.py\", line 533, in request\n    resp = self.send(prep, **send_kwargs)\n  File \"/home/amelieastbom/tdmenvs/tdmenv/lib/python3.7/site-packages/requests/sessions.py\", line 646, in send\n    r = adapter.send(request, **kwargs)\n  File \"/home/amelieastbom/tdmenvs/tdmenv/lib/python3.7/site-packages/requests/adapters.py\", line 516, in send\n    raise ConnectionError(e, request=request)\nrequests.exceptions.ConnectionError: HTTPConnectionPool(host='127.0.0.1', port=10100): Max retries exceeded with url: /set_time (Caused by NewConnectionError('<urllib3.connection.HTTPConnection object at 0x7f50ca40ead0>: Failed to establish a new connection: [Errno 111] Connection refused'))\n\nDuring handling of the above exception, another exception occurred:\n\nTraceback (most recent call last):\n  File \"/home/amelieastbom/tdm-master/tdm/tdm/backend/backend.py\", line 89, in handle_request_from_queue\n    self._handle_request(request)\n  File \"/home/amelieastbom/tdm-master/tdm/tdm/backend/backend.py\", line 115, in _handle_request\n    self._send_event_through_components_and_set_response(event)\n  File \"/home/amelieastbom/tdm-master/tdm/tdm/backend/backend.py\", line 321, in _send_event_through_components_and_set_response\n    resulting_events = self._send_event_through_components(event)\n  File \"/home/amelieastbom/tdm-master/tdm/tdm/backend/backend.py\", line 334, in _send_event_through_components\n    moves = self._dm.act(events)\n  File \"/home/amelieastbom/tdm-master/tdm/tdm/dm/component.py\", line 46, in act\n    self._act_on_queued_events()\n  File \"/home/amelieastbom/tdm-master/tdm/tdm/dm/component.py\", line 86, in _act_on_queued_events\n    self._handle_event(event)\n  File \"/home/amelieastbom/tdm-master/tdm/tdm/dm/component.py\", line 101, in _handle_event\n    self.forward_event_internally_and_externally(event)\n  File \"/home/amelieastbom/tdm-master/tdm/tdm/dm/component.py\", line 104, in forward_event_internally_and_externally\n    self._event_dispatcher.dispatch(event)\n  File \"/home/amelieastbom/tdm-master/tdm/tdm/event_dispatcher.py\", line 27, in dispatch\n    self._send_event_to_subscribing_modules(event)\n  File \"/home/amelieastbom/tdm-master/tdm/tdm/event_dispatcher.py\", line 49, in _send_event_to_subscribing_modules\n    handler, event.get_type(), event)\n  File \"/home/amelieastbom/tdm-master/tdm/tdm/event_dispatcher.py\", line 55, in _send_to_subscribing_module\n    module.process_event(protected_event)\n  File \"/home/amelieastbom/tdm-master/tdm/tdm/dm/module.py\", line 50, in process_event\n    handler()\n  File \"/home/amelieastbom/tdm-master/tdm/tdm/dm/dme_module.py\", line 66, in _handle_interpretation\n    self._set_input_event_and_run_update_and_select()\n  File \"/home/amelieastbom/tdm-master/tdm/tdm/dm/dme_module.py\", line 71, in _set_input_event_and_run_update_and_select\n    self.run_update_and_set_ddd_when_needed()\n  File \"/home/amelieastbom/tdm-master/tdm/tdm/dm/dme_module.py\", line 76, in run_update_and_set_ddd_when_needed\n    self.run_update()\n  File \"/home/amelieastbom/tdm-master/tdm/tdm/dm/dme_module.py\", line 138, in run_update\n    self.update_module.run(self._tis)\n  File \"/home/amelieastbom/tdm-master/tdm/tdm/dm/update.py\", line 274, in run\n    RuleGroup.repeat_group_sequence(self.logger, [self._exec_plan_group, self._load_plan_group], tis)\n  File \"/home/amelieastbom/tdm-master/tdm/tdm/dm/isu_rule_group.py\", line 58, in repeat_group_sequence\n    group.apply_first_applicable_rule(tis)\n  File \"/home/amelieastbom/tdm-master/tdm/tdm/dm/isu_rule_group.py\", line 19, in apply_first_applicable_rule\n    rule.apply(tis)\n  File \"/home/amelieastbom/tdm-master/tdm/tdm/dm/isu_rule.py\", line 35, in apply\n    self.apply_effects(self._ddd_component_manager, tis)\n  File \"/home/amelieastbom/tdm-master/tdm/tdm/dm/isu_rule.py\", line 45, in apply_effects\n    self.effects(ddd_component_manager, tis, *self.vars)\n  File \"/home/amelieastbom/tdm-master/tdm/tdm/dm/update_rules.py\", line 1890, in effects\n    self.perform_service_action()\n  File \"/home/amelieastbom/tdm-master/tdm/tdm/dm/update_rules.py\", line 1915, in perform_service_action\n    self.tis.session_id, self.facts, self.tis.language_code)\n  File \"/home/amelieastbom/tdm-master/tdm/tdm/dm/service_manager.py\", line 66, in perform\n    Context(ddd_name, facts, language_code, invocation_id))\n  File \"/home/amelieastbom/tdm-master/tdm/tdm/ddd/services/http.py\", line 135, in perform\n    headers={\"Content-type\": \"application/json\"})\n  File \"/home/amelieastbom/tdm-master/tdm/tdm/ddd/services/http.py\", line 38, in _post\n    raise HttpServiceInvocationException(str(exception))\ntdm.ddd.services.http.HttpServiceInvocationException: HTTPConnectionPool(host='127.0.0.1', port=10100): Max retries exceeded with url: /set_time (Caused by NewConnectionError('<urllib3.connection.HTTPConnection object at 0x7f50ca40ead0>: Failed to establish a new connection: [Errno 111] Connection refused'))", "level": "error", "logger": "tdm", "time": "2020-09-17T13:51:31.103237Z"}
{"event": "RequestException encountered.", "exception": "Traceback (most recent call last):\n  File \"/home/amelieastbom/tdmenvs/tdmenv/lib/python3.7/site-packages/urllib3/connection.py\", line 159, in _new_conn\n    (self._dns_host, self.port), self.timeout, **extra_kw)\n  File \"/home/amelieastbom/tdmenvs/tdmenv/lib/python3.7/site-packages/urllib3/util/connection.py\", line 80, in create_connection\n    raise err\n  File \"/home/amelieastbom/tdmenvs/tdmenv/lib/python3.7/site-packages/urllib3/util/connection.py\", line 70, in create_connection\n    sock.connect(sa)\nConnectionRefusedError: [Errno 111] Connection refused\n\nDuring handling of the above exception, another exception occurred:\n\nTraceback (most recent call last):\n  File \"/home/amelieastbom/tdmenvs/tdmenv/lib/python3.7/site-packages/urllib3/connectionpool.py\", line 600, in urlopen\n    chunked=chunked)\n  File \"/home/amelieastbom/tdmenvs/tdmenv/lib/python3.7/site-packages/urllib3/connectionpool.py\", line 354, in _make_request\n    conn.request(method, url, **httplib_request_kw)\n  File \"/usr/lib/python3.7/http/client.py\", line 1277, in request\n    self._send_request(method, url, body, headers, encode_chunked)\n  File \"/usr/lib/python3.7/http/client.py\", line 1323, in _send_request\n    self.endheaders(body, encode_chunked=encode_chunked)\n  File \"/usr/lib/python3.7/http/client.py\", line 1272, in endheaders\n    self._send_output(message_body, encode_chunked=encode_chunked)\n  File \"/usr/lib/python3.7/http/client.py\", line 1032, in _send_output\n    self.send(msg)\n  File \"/usr/lib/python3.7/http/client.py\", line 972, in send\n    self.connect()\n  File \"/home/amelieastbom/tdmenvs/tdmenv/lib/python3.7/site-packages/urllib3/connection.py\", line 181, in connect\n    conn = self._new_conn()\n  File \"/home/amelieastbom/tdmenvs/tdmenv/lib/python3.7/site-packages/urllib3/connection.py\", line 168, in _new_conn\n    self, \"Failed to establish a new connection: %s\" % e)\nurllib3.exceptions.NewConnectionError: <urllib3.connection.HTTPConnection object at 0x7f50ca46c810>: Failed to establish a new connection: [Errno 111] Connection refused\n\nDuring handling of the above exception, another exception occurred:\n\nTraceback (most recent call last):\n  File \"/home/amelieastbom/tdmenvs/tdmenv/lib/python3.7/site-packages/requests/adapters.py\", line 449, in send\n    timeout=timeout\n  File \"/home/amelieastbom/tdmenvs/tdmenv/lib/python3.7/site-packages/urllib3/connectionpool.py\", line 638, in urlopen\n    _stacktrace=sys.exc_info()[2])\n  File \"/home/amelieastbom/tdmenvs/tdmenv/lib/python3.7/site-packages/urllib3/util/retry.py\", line 399, in increment\n    raise MaxRetryError(_pool, url, error or ResponseError(cause))\nurllib3.exceptions.MaxRetryError: HTTPConnectionPool(host='127.0.0.1', port=10100): Max retries exceeded with url: /set_time (Caused by NewConnectionError('<urllib3.connection.HTTPConnection object at 0x7f50ca46c810>: Failed to establish a new connection: [Errno 111] Connection refused'))\n\nDuring handling of the above exception, another exception occurred:\n\nTraceback (most recent call last):\n  File \"/home/amelieastbom/tdm-master/tdm/tdm/ddd/services/http.py\", line 33, in _post\n    response = requests.post(self._endpoint, data=data, headers=headers, timeout=2)\n  File \"/home/amelieastbom/tdmenvs/tdmenv/lib/python3.7/site-packages/requests/api.py\", line 116, in post\n    return request('post', url, data=data, json=json, **kwargs)\n  File \"/home/amelieastbom/tdmenvs/tdmenv/lib/python3.7/site-packages/requests/api.py\", line 60, in request\n    return session.request(method=method, url=url, **kwargs)\n  File \"/home/amelieastbom/tdmenvs/tdmenv/lib/python3.7/site-packages/requests/sessions.py\", line 533, in request\n    resp = self.send(prep, **send_kwargs)\n  File \"/home/amelieastbom/tdmenvs/tdmenv/lib/python3.7/site-packages/requests/sessions.py\", line 646, in send\n    r = adapter.send(request, **kwargs)\n  File \"/home/amelieastbom/tdmenvs/tdmenv/lib/python3.7/site-packages/requests/adapters.py\", line 516, in send\n    raise ConnectionError(e, request=request)\nrequests.exceptions.ConnectionError: HTTPConnectionPool(host='127.0.0.1', port=10100): Max retries exceeded with url: /set_time (Caused by NewConnectionError('<urllib3.connection.HTTPConnection object at 0x7f50ca46c810>: Failed to establish a new connection: [Errno 111] Connection refused'))", "level": "error", "logger": "tdm", "time": "2020-09-17T13:51:31.192783Z"}
{"event": "Encountered an error. Stopping and returning backend error.", "exception": "Traceback (most recent call last):\n  File \"/home/amelieastbom/tdmenvs/tdmenv/lib/python3.7/site-packages/urllib3/connection.py\", line 159, in _new_conn\n    (self._dns_host, self.port), self.timeout, **extra_kw)\n  File \"/home/amelieastbom/tdmenvs/tdmenv/lib/python3.7/site-packages/urllib3/util/connection.py\", line 80, in create_connection\n    raise err\n  File \"/home/amelieastbom/tdmenvs/tdmenv/lib/python3.7/site-packages/urllib3/util/connection.py\", line 70, in create_connection\n    sock.connect(sa)\nConnectionRefusedError: [Errno 111] Connection refused\n\nDuring handling of the above exception, another exception occurred:\n\nTraceback (most recent call last):\n  File \"/home/amelieastbom/tdmenvs/tdmenv/lib/python3.7/site-packages/urllib3/connectionpool.py\", line 600, in urlopen\n    chunked=chunked)\n  File \"/home/amelieastbom/tdmenvs/tdmenv/lib/python3.7/site-packages/urllib3/connectionpool.py\", line 354, in _make_request\n    conn.request(method, url, **httplib_request_kw)\n  File \"/usr/lib/python3.7/http/client.py\", line 1277, in request\n    self._send_request(method, url, body, headers, encode_chunked)\n  File \"/usr/lib/python3.7/http/client.py\", line 1323, in _send_request\n    self.endheaders(body, encode_chunked=encode_chunked)\n  File \"/usr/lib/python3.7/http/client.py\", line 1272, in endheaders\n    self._send_output(message_body, encode_chunked=encode_chunked)\n  File \"/usr/lib/python3.7/http/client.py\", line 1032, in _send_output\n    self.send(msg)\n  File \"/usr/lib/python3.7/http/client.py\", line 972, in send\n    self.connect()\n  File \"/home/amelieastbom/tdmenvs/tdmenv/lib/python3.7/site-packages/urllib3/connection.py\", line 181, in connect\n    conn = self._new_conn()\n  File \"/home/amelieastbom/tdmenvs/tdmenv/lib/python3.7/site-packages/urllib3/connection.py\", line 168, in _new_conn\n    self, \"Failed to establish a new connection: %s\" % e)\nurllib3.exceptions.NewConnectionError: <urllib3.connection.HTTPConnection object at 0x7f50ca46c810>: Failed to establish a new connection: [Errno 111] Connection refused\n\nDuring handling of the above exception, another exception occurred:\n\nTraceback (most recent call last):\n  File \"/home/amelieastbom/tdmenvs/tdmenv/lib/python3.7/site-packages/requests/adapters.py\", line 449, in send\n    timeout=timeout\n  File \"/home/amelieastbom/tdmenvs/tdmenv/lib/python3.7/site-packages/urllib3/connectionpool.py\", line 638, in urlopen\n    _stacktrace=sys.exc_info()[2])\n  File \"/home/amelieastbom/tdmenvs/tdmenv/lib/python3.7/site-packages/urllib3/util/retry.py\", line 399, in increment\n    raise MaxRetryError(_pool, url, error or ResponseError(cause))\nurllib3.exceptions.MaxRetryError: HTTPConnectionPool(host='127.0.0.1', port=10100): Max retries exceeded with url: /set_time (Caused by NewConnectionError('<urllib3.connection.HTTPConnection object at 0x7f50ca46c810>: Failed to establish a new connection: [Errno 111] Connection refused'))\n\nDuring handling of the above exception, another exception occurred:\n\nTraceback (most recent call last):\n  File \"/home/amelieastbom/tdm-master/tdm/tdm/ddd/services/http.py\", line 33, in _post\n    response = requests.post(self._endpoint, data=data, headers=headers, timeout=2)\n  File \"/home/amelieastbom/tdmenvs/tdmenv/lib/python3.7/site-packages/requests/api.py\", line 116, in post\n    return request('post', url, data=data, json=json, **kwargs)\n  File \"/home/amelieastbom/tdmenvs/tdmenv/lib/python3.7/site-packages/requests/api.py\", line 60, in request\n    return session.request(method=method, url=url, **kwargs)\n  File \"/home/amelieastbom/tdmenvs/tdmenv/lib/python3.7/site-packages/requests/sessions.py\", line 533, in request\n    resp = self.send(prep, **send_kwargs)\n  File \"/home/amelieastbom/tdmenvs/tdmenv/lib/python3.7/site-packages/requests/sessions.py\", line 646, in send\n    r = adapter.send(request, **kwargs)\n  File \"/home/amelieastbom/tdmenvs/tdmenv/lib/python3.7/site-packages/requests/adapters.py\", line 516, in send\n    raise ConnectionError(e, request=request)\nrequests.exceptions.ConnectionError: HTTPConnectionPool(host='127.0.0.1', port=10100): Max retries exceeded with url: /set_time (Caused by NewConnectionError('<urllib3.connection.HTTPConnection object at 0x7f50ca46c810>: Failed to establish a new connection: [Errno 111] Connection refused'))\n\nDuring handling of the above exception, another exception occurred:\n\nTraceback (most recent call last):\n  File \"/home/amelieastbom/tdm-master/tdm/tdm/backend/backend.py\", line 89, in handle_request_from_queue\n    self._handle_request(request)\n  File \"/home/amelieastbom/tdm-master/tdm/tdm/backend/backend.py\", line 115, in _handle_request\n    self._send_event_through_components_and_set_response(event)\n  File \"/home/amelieastbom/tdm-master/tdm/tdm/backend/backend.py\", line 321, in _send_event_through_components_and_set_response\n    resulting_events = self._send_event_through_components(event)\n  File \"/home/amelieastbom/tdm-master/tdm/tdm/backend/backend.py\", line 334, in _send_event_through_components\n    moves = self._dm.act(events)\n  File \"/home/amelieastbom/tdm-master/tdm/tdm/dm/component.py\", line 46, in act\n    self._act_on_queued_events()\n  File \"/home/amelieastbom/tdm-master/tdm/tdm/dm/component.py\", line 86, in _act_on_queued_events\n    self._handle_event(event)\n  File \"/home/amelieastbom/tdm-master/tdm/tdm/dm/component.py\", line 101, in _handle_event\n    self.forward_event_internally_and_externally(event)\n  File \"/home/amelieastbom/tdm-master/tdm/tdm/dm/component.py\", line 104, in forward_event_internally_and_externally\n    self._event_dispatcher.dispatch(event)\n  File \"/home/amelieastbom/tdm-master/tdm/tdm/event_dispatcher.py\", line 27, in dispatch\n    self._send_event_to_subscribing_modules(event)\n  File \"/home/amelieastbom/tdm-master/tdm/tdm/event_dispatcher.py\", line 49, in _send_event_to_subscribing_modules\n    handler, event.get_type(), event)\n  File \"/home/amelieastbom/tdm-master/tdm/tdm/event_dispatcher.py\", line 55, in _send_to_subscribing_module\n    module.process_event(protected_event)\n  File \"/home/amelieastbom/tdm-master/tdm/tdm/dm/module.py\", line 50, in process_event\n    handler()\n  File \"/home/amelieastbom/tdm-master/tdm/tdm/dm/dme_module.py\", line 66, in _handle_interpretation\n    self._set_input_event_and_run_update_and_select()\n  File \"/home/amelieastbom/tdm-master/tdm/tdm/dm/dme_module.py\", line 71, in _set_input_event_and_run_update_and_select\n    self.run_update_and_set_ddd_when_needed()\n  File \"/home/amelieastbom/tdm-master/tdm/tdm/dm/dme_module.py\", line 76, in run_update_and_set_ddd_when_needed\n    self.run_update()\n  File \"/home/amelieastbom/tdm-master/tdm/tdm/dm/dme_module.py\", line 138, in run_update\n    self.update_module.run(self._tis)\n  File \"/home/amelieastbom/tdm-master/tdm/tdm/dm/update.py\", line 274, in run\n    RuleGroup.repeat_group_sequence(self.logger, [self._exec_plan_group, self._load_plan_group], tis)\n  File \"/home/amelieastbom/tdm-master/tdm/tdm/dm/isu_rule_group.py\", line 58, in repeat_group_sequence\n    group.apply_first_applicable_rule(tis)\n  File \"/home/amelieastbom/tdm-master/tdm/tdm/dm/isu_rule_group.py\", line 19, in apply_first_applicable_rule\n    rule.apply(tis)\n  File \"/home/amelieastbom/tdm-master/tdm/tdm/dm/isu_rule.py\", line 35, in apply\n    self.apply_effects(self._ddd_component_manager, tis)\n  File \"/home/amelieastbom/tdm-master/tdm/tdm/dm/isu_rule.py\", line 45, in apply_effects\n    self.effects(ddd_component_manager, tis, *self.vars)\n  File \"/home/amelieastbom/tdm-master/tdm/tdm/dm/update_rules.py\", line 1890, in effects\n    self.perform_service_action()\n  File \"/home/amelieastbom/tdm-master/tdm/tdm/dm/update_rules.py\", line 1915, in perform_service_action\n    self.tis.session_id, self.facts, self.tis.language_code)\n  File \"/home/amelieastbom/tdm-master/tdm/tdm/dm/service_manager.py\", line 66, in perform\n    Context(ddd_name, facts, language_code, invocation_id))\n  File \"/home/amelieastbom/tdm-master/tdm/tdm/ddd/services/http.py\", line 135, in perform\n    headers={\"Content-type\": \"application/json\"})\n  File \"/home/amelieastbom/tdm-master/tdm/tdm/ddd/services/http.py\", line 38, in _post\n    raise HttpServiceInvocationException(str(exception))\ntdm.ddd.services.http.HttpServiceInvocationException: HTTPConnectionPool(host='127.0.0.1', port=10100): Max retries exceeded with url: /set_time (Caused by NewConnectionError('<urllib3.connection.HTTPConnection object at 0x7f50ca46c810>: Failed to establish a new connection: [Errno 111] Connection refused'))", "level": "error", "logger": "tdm", "time": "2020-09-17T13:51:31.193862Z"}
{"event": "RequestException encountered.", "exception": "Traceback (most recent call last):\n  File \"/home/amelieastbom/tdmenvs/tdmenv/lib/python3.7/site-packages/urllib3/connection.py\", line 159, in _new_conn\n    (self._dns_host, self.port), self.timeout, **extra_kw)\n  File \"/home/amelieastbom/tdmenvs/tdmenv/lib/python3.7/site-packages/urllib3/util/connection.py\", line 80, in create_connection\n    raise err\n  File \"/home/amelieastbom/tdmenvs/tdmenv/lib/python3.7/site-packages/urllib3/util/connection.py\", line 70, in create_connection\n    sock.connect(sa)\nConnectionRefusedError: [Errno 111] Connection refused\n\nDuring handling of the above exception, another exception occurred:\n\nTraceback (most recent call last):\n  File \"/home/amelieastbom/tdmenvs/tdmenv/lib/python3.7/site-packages/urllib3/connectionpool.py\", line 600, in urlopen\n    chunked=chunked)\n  File \"/home/amelieastbom/tdmenvs/tdmenv/lib/python3.7/site-packages/urllib3/connectionpool.py\", line 354, in _make_request\n    conn.request(method, url, **httplib_request_kw)\n  File \"/usr/lib/python3.7/http/client.py\", line 1277, in request\n    self._send_request(method, url, body, headers, encode_chunked)\n  File \"/usr/lib/python3.7/http/client.py\", line 1323, in _send_request\n    self.endheaders(body, encode_chunked=encode_chunked)\n  File \"/usr/lib/python3.7/http/client.py\", line 1272, in endheaders\n    self._send_output(message_body, encode_chunked=encode_chunked)\n  File \"/usr/lib/python3.7/http/client.py\", line 1032, in _send_output\n    self.send(msg)\n  File \"/usr/lib/python3.7/http/client.py\", line 972, in send\n    self.connect()\n  File \"/home/amelieastbom/tdmenvs/tdmenv/lib/python3.7/site-packages/urllib3/connection.py\", line 181, in connect\n    conn = self._new_conn()\n  File \"/home/amelieastbom/tdmenvs/tdmenv/lib/python3.7/site-packages/urllib3/connection.py\", line 168, in _new_conn\n    self, \"Failed to establish a new connection: %s\" % e)\nurllib3.exceptions.NewConnectionError: <urllib3.connection.HTTPConnection object at 0x7f50ca3fa4d0>: Failed to establish a new connection: [Errno 111] Connection refused\n\nDuring handling of the above exception, another exception occurred:\n\nTraceback (most recent call last):\n  File \"/home/amelieastbom/tdmenvs/tdmenv/lib/python3.7/site-packages/requests/adapters.py\", line 449, in send\n    timeout=timeout\n  File \"/home/amelieastbom/tdmenvs/tdmenv/lib/python3.7/site-packages/urllib3/connectionpool.py\", line 638, in urlopen\n    _stacktrace=sys.exc_info()[2])\n  File \"/home/amelieastbom/tdmenvs/tdmenv/lib/python3.7/site-packages/urllib3/util/retry.py\", line 399, in increment\n    raise MaxRetryError(_pool, url, error or ResponseError(cause))\nurllib3.exceptions.MaxRetryError: HTTPConnectionPool(host='127.0.0.1', port=10100): Max retries exceeded with url: /selected_alarm_time (Caused by NewConnectionError('<urllib3.connection.HTTPConnection object at 0x7f50ca3fa4d0>: Failed to establish a new connection: [Errno 111] Connection refused'))\n\nDuring handling of the above exception, another exception occurred:\n\nTraceback (most recent call last):\n  File \"/home/amelieastbom/tdm-master/tdm/tdm/ddd/services/http.py\", line 33, in _post\n    response = requests.post(self._endpoint, data=data, headers=headers, timeout=2)\n  File \"/home/amelieastbom/tdmenvs/tdmenv/lib/python3.7/site-packages/requests/api.py\", line 116, in post\n    return request('post', url, data=data, json=json, **kwargs)\n  File \"/home/amelieastbom/tdmenvs/tdmenv/lib/python3.7/site-packages/requests/api.py\", line 60, in request\n    return session.request(method=method, url=url, **kwargs)\n  File \"/home/amelieastbom/tdmenvs/tdmenv/lib/python3.7/site-packages/requests/sessions.py\", line 533, in request\n    resp = self.send(prep, **send_kwargs)\n  File \"/home/amelieastbom/tdmenvs/tdmenv/lib/python3.7/site-packages/requests/sessions.py\", line 646, in send\n    r = adapter.send(request, **kwargs)\n  File \"/home/amelieastbom/tdmenvs/tdmenv/lib/python3.7/site-packages/requests/adapters.py\", line 516, in send\n    raise ConnectionError(e, request=request)\nrequests.exceptions.ConnectionError: HTTPConnectionPool(host='127.0.0.1', port=10100): Max retries exceeded with url: /selected_alarm_time (Caused by NewConnectionError('<urllib3.connection.HTTPConnection object at 0x7f50ca3fa4d0>: Failed to establish a new connection: [Errno 111] Connection refused'))", "level": "error", "logger": "tdm", "time": "2020-09-17T13:51:31.380401Z"}
{"event": "Encountered an error. Stopping and returning backend error.", "exception": "Traceback (most recent call last):\n  File \"/home/amelieastbom/tdmenvs/tdmenv/lib/python3.7/site-packages/urllib3/connection.py\", line 159, in _new_conn\n    (self._dns_host, self.port), self.timeout, **extra_kw)\n  File \"/home/amelieastbom/tdmenvs/tdmenv/lib/python3.7/site-packages/urllib3/util/connection.py\", line 80, in create_connection\n    raise err\n  File \"/home/amelieastbom/tdmenvs/tdmenv/lib/python3.7/site-packages/urllib3/util/connection.py\", line 70, in create_connection\n    sock.connect(sa)\nConnectionRefusedError: [Errno 111] Connection refused\n\nDuring handling of the above exception, another exception occurred:\n\nTraceback (most recent call last):\n  File \"/home/amelieastbom/tdmenvs/tdmenv/lib/python3.7/site-packages/urllib3/connectionpool.py\", line 600, in urlopen\n    chunked=chunked)\n  File \"/home/amelieastbom/tdmenvs/tdmenv/lib/python3.7/site-packages/urllib3/connectionpool.py\", line 354, in _make_request\n    conn.request(method, url, **httplib_request_kw)\n  File \"/usr/lib/python3.7/http/client.py\", line 1277, in request\n    self._send_request(method, url, body, headers, encode_chunked)\n  File \"/usr/lib/python3.7/http/client.py\", line 1323, in _send_request\n    self.endheaders(body, encode_chunked=encode_chunked)\n  File \"/usr/lib/python3.7/http/client.py\", line 1272, in endheaders\n    self._send_output(message_body, encode_chunked=encode_chunked)\n  File \"/usr/lib/python3.7/http/client.py\", line 1032, in _send_output\n    self.send(msg)\n  File \"/usr/lib/python3.7/http/client.py\", line 972, in send\n    self.connect()\n  File \"/home/amelieastbom/tdmenvs/tdmenv/lib/python3.7/site-packages/urllib3/connection.py\", line 181, in connect\n    conn = self._new_conn()\n  File \"/home/amelieastbom/tdmenvs/tdmenv/lib/python3.7/site-packages/urllib3/connection.py\", line 168, in _new_conn\n    self, \"Failed to establish a new connection: %s\" % e)\nurllib3.exceptions.NewConnectionError: <urllib3.connection.HTTPConnection object at 0x7f50ca3fa4d0>: Failed to establish a new connection: [Errno 111] Connection refused\n\nDuring handling of the above exception, another exception occurred:\n\nTraceback (most recent call last):\n  File \"/home/amelieastbom/tdmenvs/tdmenv/lib/python3.7/site-packages/requests/adapters.py\", line 449, in send\n    timeout=timeout\n  File \"/home/amelieastbom/tdmenvs/tdmenv/lib/python3.7/site-packages/urllib3/connectionpool.py\", line 638, in urlopen\n    _stacktrace=sys.exc_info()[2])\n  File \"/home/amelieastbom/tdmenvs/tdmenv/lib/python3.7/site-packages/urllib3/util/retry.py\", line 399, in increment\n    raise MaxRetryError(_pool, url, error or ResponseError(cause))\nurllib3.exceptions.MaxRetryError: HTTPConnectionPool(host='127.0.0.1', port=10100): Max retries exceeded with url: /selected_alarm_time (Caused by NewConnectionError('<urllib3.connection.HTTPConnection object at 0x7f50ca3fa4d0>: Failed to establish a new connection: [Errno 111] Connection refused'))\n\nDuring handling of the above exception, another exception occurred:\n\nTraceback (most recent call last):\n  File \"/home/amelieastbom/tdm-master/tdm/tdm/ddd/services/http.py\", line 33, in _post\n    response = requests.post(self._endpoint, data=data, headers=headers, timeout=2)\n  File \"/home/amelieastbom/tdmenvs/tdmenv/lib/python3.7/site-packages/requests/api.py\", line 116, in post\n    return request('post', url, data=data, json=json, **kwargs)\n  File \"/home/amelieastbom/tdmenvs/tdmenv/lib/python3.7/site-packages/requests/api.py\", line 60, in request\n    return session.request(method=method, url=url, **kwargs)\n  File \"/home/amelieastbom/tdmenvs/tdmenv/lib/python3.7/site-packages/requests/sessions.py\", line 533, in request\n    resp = self.send(prep, **send_kwargs)\n  File \"/home/amelieastbom/tdmenvs/tdmenv/lib/python3.7/site-packages/requests/sessions.py\", line 646, in send\n    r = adapter.send(request, **kwargs)\n  File \"/home/amelieastbom/tdmenvs/tdmenv/lib/python3.7/site-packages/requests/adapters.py\", line 516, in send\n    raise ConnectionError(e, request=request)\nrequests.exceptions.ConnectionError: HTTPConnectionPool(host='127.0.0.1', port=10100): Max retries exceeded with url: /selected_alarm_time (Caused by NewConnectionError('<urllib3.connection.HTTPConnection object at 0x7f50ca3fa4d0>: Failed to establish a new connection: [Errno 111] Connection refused'))\n\nDuring handling of the above exception, another exception occurred:\n\nTraceback (most recent call last):\n  File \"/home/amelieastbom/tdm-master/tdm/tdm/backend/backend.py\", line 89, in handle_request_from_queue\n    self._handle_request(request)\n  File \"/home/amelieastbom/tdm-master/tdm/tdm/backend/backend.py\", line 115, in _handle_request\n    self._send_event_through_components_and_set_response(event)\n  File \"/home/amelieastbom/tdm-master/tdm/tdm/backend/backend.py\", line 321, in _send_event_through_components_and_set_response\n    resulting_events = self._send_event_through_components(event)\n  File \"/home/amelieastbom/tdm-master/tdm/tdm/backend/backend.py\", line 334, in _send_event_through_components\n    moves = self._dm.act(events)\n  File \"/home/amelieastbom/tdm-master/tdm/tdm/dm/component.py\", line 46, in act\n    self._act_on_queued_events()\n  File \"/home/amelieastbom/tdm-master/tdm/tdm/dm/component.py\", line 86, in _act_on_queued_events\n    self._handle_event(event)\n  File \"/home/amelieastbom/tdm-master/tdm/tdm/dm/component.py\", line 101, in _handle_event\n    self.forward_event_internally_and_externally(event)\n  File \"/home/amelieastbom/tdm-master/tdm/tdm/dm/component.py\", line 104, in forward_event_internally_and_externally\n    self._event_dispatcher.dispatch(event)\n  File \"/home/amelieastbom/tdm-master/tdm/tdm/event_dispatcher.py\", line 27, in dispatch\n    self._send_event_to_subscribing_modules(event)\n  File \"/home/amelieastbom/tdm-master/tdm/tdm/event_dispatcher.py\", line 49, in _send_event_to_subscribing_modules\n    handler, event.get_type(), event)\n  File \"/home/amelieastbom/tdm-master/tdm/tdm/event_dispatcher.py\", line 55, in _send_to_subscribing_module\n    module.process_event(protected_event)\n  File \"/home/amelieastbom/tdm-master/tdm/tdm/dm/module.py\", line 50, in process_event\n    handler()\n  File \"/home/amelieastbom/tdm-master/tdm/tdm/dm/dme_module.py\", line 66, in _handle_interpretation\n    self._set_input_event_and_run_update_and_select()\n  File \"/home/amelieastbom/tdm-master/tdm/tdm/dm/dme_module.py\", line 71, in _set_input_event_and_run_update_and_select\n    self.run_update_and_set_ddd_when_needed()\n  File \"/home/amelieastbom/tdm-master/tdm/tdm/dm/dme_module.py\", line 76, in run_update_and_set_ddd_when_needed\n    self.run_update()\n  File \"/home/amelieastbom/tdm-master/tdm/tdm/dm/dme_module.py\", line 138, in run_update\n    self.update_module.run(self._tis)\n  File \"/home/amelieastbom/tdm-master/tdm/tdm/dm/update.py\", line 274, in run\n    RuleGroup.repeat_group_sequence(self.logger, [self._exec_plan_group, self._load_plan_group], tis)\n  File \"/home/amelieastbom/tdm-master/tdm/tdm/dm/isu_rule_group.py\", line 57, in repeat_group_sequence\n    if any(group._applicable_rules(tis)):\n  File \"/home/amelieastbom/tdm-master/tdm/tdm/dm/isu_rule_group.py\", line 34, in <genexpr>\n    return (rule for rule in self._rules if rule.is_applicable(tis))\n  File \"/home/amelieastbom/tdm-master/tdm/tdm/dm/isu_rule.py\", line 26, in is_applicable\n    return self.test_preconditions(self._ddd_component_manager, tis)\n  File \"/home/amelieastbom/tdm-master/tdm/tdm/dm/isu_rule.py\", line 31, in test_preconditions\n    return self.preconditions(ddd_component_manager, self.tis)\n  File \"/home/amelieastbom/tdm-master/tdm/tdm/dm/update_rules.py\", line 1715, in preconditions\n    for (question, result) in tis.get_resolving_results_from_services():\n  File \"/home/amelieastbom/tdm-master/tdm/tdm/dm/tis.py\", line 1441, in get_resolving_results_from_services\n    all_results = self.service_manager.query(question, self.session_id, self.shared.com, self.language_code)\n  File \"/home/amelieastbom/tdm-master/tdm/tdm/dm/service_manager.py\", line 202, in query\n    results = get_query_results_for_interface(ddd, interface)\n  File \"/home/amelieastbom/tdm-master/tdm/tdm/dm/service_manager.py\", line 185, in get_query_results_for_interface\n    return service_wrapper.query(question, parameters, min_results, max_results, session, context)\n  File \"/home/amelieastbom/tdm-master/tdm/tdm/ddd/services/http.py\", line 159, in query\n    headers={\"Content-type\": \"application/json\"})\n  File \"/home/amelieastbom/tdm-master/tdm/tdm/ddd/services/http.py\", line 38, in _post\n    raise HttpServiceInvocationException(str(exception))\ntdm.ddd.services.http.HttpServiceInvocationException: HTTPConnectionPool(host='127.0.0.1', port=10100): Max retries exceeded with url: /selected_alarm_time (Caused by NewConnectionError('<urllib3.connection.HTTPConnection object at 0x7f50ca3fa4d0>: Failed to establish a new connection: [Errno 111] Connection refused'))", "level": "error", "logger": "tdm", "time": "2020-09-17T13:51:31.381738Z"}
{"event": "RequestException encountered.", "exception": "Traceback (most recent call last):\n  File \"/home/amelieastbom/tdmenvs/tdmenv/lib/python3.7/site-packages/urllib3/connection.py\", line 159, in _new_conn\n    (self._dns_host, self.port), self.timeout, **extra_kw)\n  File \"/home/amelieastbom/tdmenvs/tdmenv/lib/python3.7/site-packages/urllib3/util/connection.py\", line 80, in create_connection\n    raise err\n  File \"/home/amelieastbom/tdmenvs/tdmenv/lib/python3.7/site-packages/urllib3/util/connection.py\", line 70, in create_connection\n    sock.connect(sa)\nConnectionRefusedError: [Errno 111] Connection refused\n\nDuring handling of the above exception, another exception occurred:\n\nTraceback (most recent call last):\n  File \"/home/amelieastbom/tdmenvs/tdmenv/lib/python3.7/site-packages/urllib3/connectionpool.py\", line 600, in urlopen\n    chunked=chunked)\n  File \"/home/amelieastbom/tdmenvs/tdmenv/lib/python3.7/site-packages/urllib3/connectionpool.py\", line 354, in _make_request\n    conn.request(method, url, **httplib_request_kw)\n  File \"/usr/lib/python3.7/http/client.py\", line 1277, in request\n    self._send_request(method, url, body, headers, encode_chunked)\n  File \"/usr/lib/python3.7/http/client.py\", line 1323, in _send_request\n    self.endheaders(body, encode_chunked=encode_chunked)\n  File \"/usr/lib/python3.7/http/client.py\", line 1272, in endheaders\n    self._send_output(message_body, encode_chunked=encode_chunked)\n  File \"/usr/lib/python3.7/http/client.py\", line 1032, in _send_output\n    self.send(msg)\n  File \"/usr/lib/python3.7/http/client.py\", line 972, in send\n    self.connect()\n  File \"/home/amelieastbom/tdmenvs/tdmenv/lib/python3.7/site-packages/urllib3/connection.py\", line 181, in connect\n    conn = self._new_conn()\n  File \"/home/amelieastbom/tdmenvs/tdmenv/lib/python3.7/site-packages/urllib3/connection.py\", line 168, in _new_conn\n    self, \"Failed to establish a new connection: %s\" % e)\nurllib3.exceptions.NewConnectionError: <urllib3.connection.HTTPConnection object at 0x7f50c9b9c650>: Failed to establish a new connection: [Errno 111] Connection refused\n\nDuring handling of the above exception, another exception occurred:\n\nTraceback (most recent call last):\n  File \"/home/amelieastbom/tdmenvs/tdmenv/lib/python3.7/site-packages/requests/adapters.py\", line 449, in send\n    timeout=timeout\n  File \"/home/amelieastbom/tdmenvs/tdmenv/lib/python3.7/site-packages/urllib3/connectionpool.py\", line 638, in urlopen\n    _stacktrace=sys.exc_info()[2])\n  File \"/home/amelieastbom/tdmenvs/tdmenv/lib/python3.7/site-packages/urllib3/util/retry.py\", line 399, in increment\n    raise MaxRetryError(_pool, url, error or ResponseError(cause))\nurllib3.exceptions.MaxRetryError: HTTPConnectionPool(host='127.0.0.1', port=10100): Max retries exceeded with url: /set_alarm (Caused by NewConnectionError('<urllib3.connection.HTTPConnection object at 0x7f50c9b9c650>: Failed to establish a new connection: [Errno 111] Connection refused'))\n\nDuring handling of the above exception, another exception occurred:\n\nTraceback (most recent call last):\n  File \"/home/amelieastbom/tdm-master/tdm/tdm/ddd/services/http.py\", line 33, in _post\n    response = requests.post(self._endpoint, data=data, headers=headers, timeout=2)\n  File \"/home/amelieastbom/tdmenvs/tdmenv/lib/python3.7/site-packages/requests/api.py\", line 116, in post\n    return request('post', url, data=data, json=json, **kwargs)\n  File \"/home/amelieastbom/tdmenvs/tdmenv/lib/python3.7/site-packages/requests/api.py\", line 60, in request\n    return session.request(method=method, url=url, **kwargs)\n  File \"/home/amelieastbom/tdmenvs/tdmenv/lib/python3.7/site-packages/requests/sessions.py\", line 533, in request\n    resp = self.send(prep, **send_kwargs)\n  File \"/home/amelieastbom/tdmenvs/tdmenv/lib/python3.7/site-packages/requests/sessions.py\", line 646, in send\n    r = adapter.send(request, **kwargs)\n  File \"/home/amelieastbom/tdmenvs/tdmenv/lib/python3.7/site-packages/requests/adapters.py\", line 516, in send\n    raise ConnectionError(e, request=request)\nrequests.exceptions.ConnectionError: HTTPConnectionPool(host='127.0.0.1', port=10100): Max retries exceeded with url: /set_alarm (Caused by NewConnectionError('<urllib3.connection.HTTPConnection object at 0x7f50c9b9c650>: Failed to establish a new connection: [Errno 111] Connection refused'))", "level": "error", "logger": "tdm", "time": "2020-09-17T13:51:31.489899Z"}
{"event": "Encountered an error. Stopping and returning backend error.", "exception": "Traceback (most recent call last):\n  File \"/home/amelieastbom/tdmenvs/tdmenv/lib/python3.7/site-packages/urllib3/connection.py\", line 159, in _new_conn\n    (self._dns_host, self.port), self.timeout, **extra_kw)\n  File \"/home/amelieastbom/tdmenvs/tdmenv/lib/python3.7/site-packages/urllib3/util/connection.py\", line 80, in create_connection\n    raise err\n  File \"/home/amelieastbom/tdmenvs/tdmenv/lib/python3.7/site-packages/urllib3/util/connection.py\", line 70, in create_connection\n    sock.connect(sa)\nConnectionRefusedError: [Errno 111] Connection refused\n\nDuring handling of the above exception, another exception occurred:\n\nTraceback (most recent call last):\n  File \"/home/amelieastbom/tdmenvs/tdmenv/lib/python3.7/site-packages/urllib3/connectionpool.py\", line 600, in urlopen\n    chunked=chunked)\n  File \"/home/amelieastbom/tdmenvs/tdmenv/lib/python3.7/site-packages/urllib3/connectionpool.py\", line 354, in _make_request\n    conn.request(method, url, **httplib_request_kw)\n  File \"/usr/lib/python3.7/http/client.py\", line 1277, in request\n    self._send_request(method, url, body, headers, encode_chunked)\n  File \"/usr/lib/python3.7/http/client.py\", line 1323, in _send_request\n    self.endheaders(body, encode_chunked=encode_chunked)\n  File \"/usr/lib/python3.7/http/client.py\", line 1272, in endheaders\n    self._send_output(message_body, encode_chunked=encode_chunked)\n  File \"/usr/lib/python3.7/http/client.py\", line 1032, in _send_output\n    self.send(msg)\n  File \"/usr/lib/python3.7/http/client.py\", line 972, in send\n    self.connect()\n  File \"/home/amelieastbom/tdmenvs/tdmenv/lib/python3.7/site-packages/urllib3/connection.py\", line 181, in connect\n    conn = self._new_conn()\n  File \"/home/amelieastbom/tdmenvs/tdmenv/lib/python3.7/site-packages/urllib3/connection.py\", line 168, in _new_conn\n    self, \"Failed to establish a new connection: %s\" % e)\nurllib3.exceptions.NewConnectionError: <urllib3.connection.HTTPConnection object at 0x7f50c9b9c650>: Failed to establish a new connection: [Errno 111] Connection refused\n\nDuring handling of the above exception, another exception occurred:\n\nTraceback (most recent call last):\n  File \"/home/amelieastbom/tdmenvs/tdmenv/lib/python3.7/site-packages/requests/adapters.py\", line 449, in send\n    timeout=timeout\n  File \"/home/amelieastbom/tdmenvs/tdmenv/lib/python3.7/site-packages/urllib3/connectionpool.py\", line 638, in urlopen\n    _stacktrace=sys.exc_info()[2])\n  File \"/home/amelieastbom/tdmenvs/tdmenv/lib/python3.7/site-packages/urllib3/util/retry.py\", line 399, in increment\n    raise MaxRetryError(_pool, url, error or ResponseError(cause))\nurllib3.exceptions.MaxRetryError: HTTPConnectionPool(host='127.0.0.1', port=10100): Max retries exceeded with url: /set_alarm (Caused by NewConnectionError('<urllib3.connection.HTTPConnection object at 0x7f50c9b9c650>: Failed to establish a new connection: [Errno 111] Connection refused'))\n\nDuring handling of the above exception, another exception occurred:\n\nTraceback (most recent call last):\n  File \"/home/amelieastbom/tdm-master/tdm/tdm/ddd/services/http.py\", line 33, in _post\n    response = requests.post(self._endpoint, data=data, headers=headers, timeout=2)\n  File \"/home/amelieastbom/tdmenvs/tdmenv/lib/python3.7/site-packages/requests/api.py\", line 116, in post\n    return request('post', url, data=data, json=json, **kwargs)\n  File \"/home/amelieastbom/tdmenvs/tdmenv/lib/python3.7/site-packages/requests/api.py\", line 60, in request\n    return session.request(method=method, url=url, **kwargs)\n  File \"/home/amelieastbom/tdmenvs/tdmenv/lib/python3.7/site-packages/requests/sessions.py\", line 533, in request\n    resp = self.send(prep, **send_kwargs)\n  File \"/home/amelieastbom/tdmenvs/tdmenv/lib/python3.7/site-packages/requests/sessions.py\", line 646, in send\n    r = adapter.send(request, **kwargs)\n  File \"/home/amelieastbom/tdmenvs/tdmenv/lib/python3.7/site-packages/requests/adapters.py\", line 516, in send\n    raise ConnectionError(e, request=request)\nrequests.exceptions.ConnectionError: HTTPConnectionPool(host='127.0.0.1', port=10100): Max retries exceeded with url: /set_alarm (Caused by NewConnectionError('<urllib3.connection.HTTPConnection object at 0x7f50c9b9c650>: Failed to establish a new connection: [Errno 111] Connection refused'))\n\nDuring handling of the above exception, another exception occurred:\n\nTraceback (most recent call last):\n  File \"/home/amelieastbom/tdm-master/tdm/tdm/backend/backend.py\", line 89, in handle_request_from_queue\n    self._handle_request(request)\n  File \"/home/amelieastbom/tdm-master/tdm/tdm/backend/backend.py\", line 115, in _handle_request\n    self._send_event_through_components_and_set_response(event)\n  File \"/home/amelieastbom/tdm-master/tdm/tdm/backend/backend.py\", line 321, in _send_event_through_components_and_set_response\n    resulting_events = self._send_event_through_components(event)\n  File \"/home/amelieastbom/tdm-master/tdm/tdm/backend/backend.py\", line 334, in _send_event_through_components\n    moves = self._dm.act(events)\n  File \"/home/amelieastbom/tdm-master/tdm/tdm/dm/component.py\", line 46, in act\n    self._act_on_queued_events()\n  File \"/home/amelieastbom/tdm-master/tdm/tdm/dm/component.py\", line 86, in _act_on_queued_events\n    self._handle_event(event)\n  File \"/home/amelieastbom/tdm-master/tdm/tdm/dm/component.py\", line 101, in _handle_event\n    self.forward_event_internally_and_externally(event)\n  File \"/home/amelieastbom/tdm-master/tdm/tdm/dm/component.py\", line 104, in forward_event_internally_and_externally\n    self._event_dispatcher.dispatch(event)\n  File \"/home/amelieastbom/tdm-master/tdm/tdm/event_dispatcher.py\", line 27, in dispatch\n    self._send_event_to_subscribing_modules(event)\n  File \"/home/amelieastbom/tdm-master/tdm/tdm/event_dispatcher.py\", line 49, in _send_event_to_subscribing_modules\n    handler, event.get_type(), event)\n  File \"/home/amelieastbom/tdm-master/tdm/tdm/event_dispatcher.py\", line 55, in _send_to_subscribing_module\n    module.process_event(protected_event)\n  File \"/home/amelieastbom/tdm-master/tdm/tdm/dm/module.py\", line 50, in process_event\n    handler()\n  File \"/home/amelieastbom/tdm-master/tdm/tdm/dm/dme_module.py\", line 66, in _handle_interpretation\n    self._set_input_event_and_run_update_and_select()\n  File \"/home/amelieastbom/tdm-master/tdm/tdm/dm/dme_module.py\", line 71, in _set_input_event_and_run_update_and_select\n    self.run_update_and_set_ddd_when_needed()\n  File \"/home/amelieastbom/tdm-master/tdm/tdm/dm/dme_module.py\", line 76, in run_update_and_set_ddd_when_needed\n    self.run_update()\n  File \"/home/amelieastbom/tdm-master/tdm/tdm/dm/dme_module.py\", line 138, in run_update\n    self.update_module.run(self._tis)\n  File \"/home/amelieastbom/tdm-master/tdm/tdm/dm/update.py\", line 274, in run\n    RuleGroup.repeat_group_sequence(self.logger, [self._exec_plan_group, self._load_plan_group], tis)\n  File \"/home/amelieastbom/tdm-master/tdm/tdm/dm/isu_rule_group.py\", line 58, in repeat_group_sequence\n    group.apply_first_applicable_rule(tis)\n  File \"/home/amelieastbom/tdm-master/tdm/tdm/dm/isu_rule_group.py\", line 19, in apply_first_applicable_rule\n    rule.apply(tis)\n  File \"/home/amelieastbom/tdm-master/tdm/tdm/dm/isu_rule.py\", line 35, in apply\n    self.apply_effects(self._ddd_component_manager, tis)\n  File \"/home/amelieastbom/tdm-master/tdm/tdm/dm/isu_rule.py\", line 45, in apply_effects\n    self.effects(ddd_component_manager, tis, *self.vars)\n  File \"/home/amelieastbom/tdm-master/tdm/tdm/dm/update_rules.py\", line 1890, in effects\n    self.perform_service_action()\n  File \"/home/amelieastbom/tdm-master/tdm/tdm/dm/update_rules.py\", line 1915, in perform_service_action\n    self.tis.session_id, self.facts, self.tis.language_code)\n  File \"/home/amelieastbom/tdm-master/tdm/tdm/dm/service_manager.py\", line 66, in perform\n    Context(ddd_name, facts, language_code, invocation_id))\n  File \"/home/amelieastbom/tdm-master/tdm/tdm/ddd/services/http.py\", line 135, in perform\n    headers={\"Content-type\": \"application/json\"})\n  File \"/home/amelieastbom/tdm-master/tdm/tdm/ddd/services/http.py\", line 38, in _post\n    raise HttpServiceInvocationException(str(exception))\ntdm.ddd.services.http.HttpServiceInvocationException: HTTPConnectionPool(host='127.0.0.1', port=10100): Max retries exceeded with url: /set_alarm (Caused by NewConnectionError('<urllib3.connection.HTTPConnection object at 0x7f50c9b9c650>: Failed to establish a new connection: [Errno 111] Connection refused'))", "level": "error", "logger": "tdm", "time": "2020-09-17T13:51:31.491386Z"}
{"event": "RequestException encountered.", "exception": "Traceback (most recent call last):\n  File \"/home/amelieastbom/tdmenvs/tdmenv/lib/python3.7/site-packages/urllib3/connection.py\", line 159, in _new_conn\n    (self._dns_host, self.port), self.timeout, **extra_kw)\n  File \"/home/amelieastbom/tdmenvs/tdmenv/lib/python3.7/site-packages/urllib3/util/connection.py\", line 80, in create_connection\n    raise err\n  File \"/home/amelieastbom/tdmenvs/tdmenv/lib/python3.7/site-packages/urllib3/util/connection.py\", line 70, in create_connection\n    sock.connect(sa)\nConnectionRefusedError: [Errno 111] Connection refused\n\nDuring handling of the above exception, another exception occurred:\n\nTraceback (most recent call last):\n  File \"/home/amelieastbom/tdmenvs/tdmenv/lib/python3.7/site-packages/urllib3/connectionpool.py\", line 600, in urlopen\n    chunked=chunked)\n  File \"/home/amelieastbom/tdmenvs/tdmenv/lib/python3.7/site-packages/urllib3/connectionpool.py\", line 354, in _make_request\n    conn.request(method, url, **httplib_request_kw)\n  File \"/usr/lib/python3.7/http/client.py\", line 1277, in request\n    self._send_request(method, url, body, headers, encode_chunked)\n  File \"/usr/lib/python3.7/http/client.py\", line 1323, in _send_request\n    self.endheaders(body, encode_chunked=encode_chunked)\n  File \"/usr/lib/python3.7/http/client.py\", line 1272, in endheaders\n    self._send_output(message_body, encode_chunked=encode_chunked)\n  File \"/usr/lib/python3.7/http/client.py\", line 1032, in _send_output\n    self.send(msg)\n  File \"/usr/lib/python3.7/http/client.py\", line 972, in send\n    self.connect()\n  File \"/home/amelieastbom/tdmenvs/tdmenv/lib/python3.7/site-packages/urllib3/connection.py\", line 181, in connect\n    conn = self._new_conn()\n  File \"/home/amelieastbom/tdmenvs/tdmenv/lib/python3.7/site-packages/urllib3/connection.py\", line 168, in _new_conn\n    self, \"Failed to establish a new connection: %s\" % e)\nurllib3.exceptions.NewConnectionError: <urllib3.connection.HTTPConnection object at 0x7f50c9bb9ed0>: Failed to establish a new connection: [Errno 111] Connection refused\n\nDuring handling of the above exception, another exception occurred:\n\nTraceback (most recent call last):\n  File \"/home/amelieastbom/tdmenvs/tdmenv/lib/python3.7/site-packages/requests/adapters.py\", line 449, in send\n    timeout=timeout\n  File \"/home/amelieastbom/tdmenvs/tdmenv/lib/python3.7/site-packages/urllib3/connectionpool.py\", line 638, in urlopen\n    _stacktrace=sys.exc_info()[2])\n  File \"/home/amelieastbom/tdmenvs/tdmenv/lib/python3.7/site-packages/urllib3/util/retry.py\", line 399, in increment\n    raise MaxRetryError(_pool, url, error or ResponseError(cause))\nurllib3.exceptions.MaxRetryError: HTTPConnectionPool(host='127.0.0.1', port=10100): Max retries exceeded with url: /selected_alarm_time (Caused by NewConnectionError('<urllib3.connection.HTTPConnection object at 0x7f50c9bb9ed0>: Failed to establish a new connection: [Errno 111] Connection refused'))\n\nDuring handling of the above exception, another exception occurred:\n\nTraceback (most recent call last):\n  File \"/home/amelieastbom/tdm-master/tdm/tdm/ddd/services/http.py\", line 33, in _post\n    response = requests.post(self._endpoint, data=data, headers=headers, timeout=2)\n  File \"/home/amelieastbom/tdmenvs/tdmenv/lib/python3.7/site-packages/requests/api.py\", line 116, in post\n    return request('post', url, data=data, json=json, **kwargs)\n  File \"/home/amelieastbom/tdmenvs/tdmenv/lib/python3.7/site-packages/requests/api.py\", line 60, in request\n    return session.request(method=method, url=url, **kwargs)\n  File \"/home/amelieastbom/tdmenvs/tdmenv/lib/python3.7/site-packages/requests/sessions.py\", line 533, in request\n    resp = self.send(prep, **send_kwargs)\n  File \"/home/amelieastbom/tdmenvs/tdmenv/lib/python3.7/site-packages/requests/sessions.py\", line 646, in send\n    r = adapter.send(request, **kwargs)\n  File \"/home/amelieastbom/tdmenvs/tdmenv/lib/python3.7/site-packages/requests/adapters.py\", line 516, in send\n    raise ConnectionError(e, request=request)\nrequests.exceptions.ConnectionError: HTTPConnectionPool(host='127.0.0.1', port=10100): Max retries exceeded with url: /selected_alarm_time (Caused by NewConnectionError('<urllib3.connection.HTTPConnection object at 0x7f50c9bb9ed0>: Failed to establish a new connection: [Errno 111] Connection refused'))", "level": "error", "logger": "tdm", "time": "2020-09-17T13:51:31.594992Z"}
{"event": "Encountered an error. Stopping and returning backend error.", "exception": "Traceback (most recent call last):\n  File \"/home/amelieastbom/tdmenvs/tdmenv/lib/python3.7/site-packages/urllib3/connection.py\", line 159, in _new_conn\n    (self._dns_host, self.port), self.timeout, **extra_kw)\n  File \"/home/amelieastbom/tdmenvs/tdmenv/lib/python3.7/site-packages/urllib3/util/connection.py\", line 80, in create_connection\n    raise err\n  File \"/home/amelieastbom/tdmenvs/tdmenv/lib/python3.7/site-packages/urllib3/util/connection.py\", line 70, in create_connection\n    sock.connect(sa)\nConnectionRefusedError: [Errno 111] Connection refused\n\nDuring handling of the above exception, another exception occurred:\n\nTraceback (most recent call last):\n  File \"/home/amelieastbom/tdmenvs/tdmenv/lib/python3.7/site-packages/urllib3/connectionpool.py\", line 600, in urlopen\n    chunked=chunked)\n  File \"/home/amelieastbom/tdmenvs/tdmenv/lib/python3.7/site-packages/urllib3/connectionpool.py\", line 354, in _make_request\n    conn.request(method, url, **httplib_request_kw)\n  File \"/usr/lib/python3.7/http/client.py\", line 1277, in request\n    self._send_request(method, url, body, headers, encode_chunked)\n  File \"/usr/lib/python3.7/http/client.py\", line 1323, in _send_request\n    self.endheaders(body, encode_chunked=encode_chunked)\n  File \"/usr/lib/python3.7/http/client.py\", line 1272, in endheaders\n    self._send_output(message_body, encode_chunked=encode_chunked)\n  File \"/usr/lib/python3.7/http/client.py\", line 1032, in _send_output\n    self.send(msg)\n  File \"/usr/lib/python3.7/http/client.py\", line 972, in send\n    self.connect()\n  File \"/home/amelieastbom/tdmenvs/tdmenv/lib/python3.7/site-packages/urllib3/connection.py\", line 181, in connect\n    conn = self._new_conn()\n  File \"/home/amelieastbom/tdmenvs/tdmenv/lib/python3.7/site-packages/urllib3/connection.py\", line 168, in _new_conn\n    self, \"Failed to establish a new connection: %s\" % e)\nurllib3.exceptions.NewConnectionError: <urllib3.connection.HTTPConnection object at 0x7f50c9bb9ed0>: Failed to establish a new connection: [Errno 111] Connection refused\n\nDuring handling of the above exception, another exception occurred:\n\nTraceback (most recent call last):\n  File \"/home/amelieastbom/tdmenvs/tdmenv/lib/python3.7/site-packages/requests/adapters.py\", line 449, in send\n    timeout=timeout\n  File \"/home/amelieastbom/tdmenvs/tdmenv/lib/python3.7/site-packages/urllib3/connectionpool.py\", line 638, in urlopen\n    _stacktrace=sys.exc_info()[2])\n  File \"/home/amelieastbom/tdmenvs/tdmenv/lib/python3.7/site-packages/urllib3/util/retry.py\", line 399, in increment\n    raise MaxRetryError(_pool, url, error or ResponseError(cause))\nurllib3.exceptions.MaxRetryError: HTTPConnectionPool(host='127.0.0.1', port=10100): Max retries exceeded with url: /selected_alarm_time (Caused by NewConnectionError('<urllib3.connection.HTTPConnection object at 0x7f50c9bb9ed0>: Failed to establish a new connection: [Errno 111] Connection refused'))\n\nDuring handling of the above exception, another exception occurred:\n\nTraceback (most recent call last):\n  File \"/home/amelieastbom/tdm-master/tdm/tdm/ddd/services/http.py\", line 33, in _post\n    response = requests.post(self._endpoint, data=data, headers=headers, timeout=2)\n  File \"/home/amelieastbom/tdmenvs/tdmenv/lib/python3.7/site-packages/requests/api.py\", line 116, in post\n    return request('post', url, data=data, json=json, **kwargs)\n  File \"/home/amelieastbom/tdmenvs/tdmenv/lib/python3.7/site-packages/requests/api.py\", line 60, in request\n    return session.request(method=method, url=url, **kwargs)\n  File \"/home/amelieastbom/tdmenvs/tdmenv/lib/python3.7/site-packages/requests/sessions.py\", line 533, in request\n    resp = self.send(prep, **send_kwargs)\n  File \"/home/amelieastbom/tdmenvs/tdmenv/lib/python3.7/site-packages/requests/sessions.py\", line 646, in send\n    r = adapter.send(request, **kwargs)\n  File \"/home/amelieastbom/tdmenvs/tdmenv/lib/python3.7/site-packages/requests/adapters.py\", line 516, in send\n    raise ConnectionError(e, request=request)\nrequests.exceptions.ConnectionError: HTTPConnectionPool(host='127.0.0.1', port=10100): Max retries exceeded with url: /selected_alarm_time (Caused by NewConnectionError('<urllib3.connection.HTTPConnection object at 0x7f50c9bb9ed0>: Failed to establish a new connection: [Errno 111] Connection refused'))\n\nDuring handling of the above exception, another exception occurred:\n\nTraceback (most recent call last):\n  File \"/home/amelieastbom/tdm-master/tdm/tdm/backend/backend.py\", line 89, in handle_request_from_queue\n    self._handle_request(request)\n  File \"/home/amelieastbom/tdm-master/tdm/tdm/backend/backend.py\", line 115, in _handle_request\n    self._send_event_through_components_and_set_response(event)\n  File \"/home/amelieastbom/tdm-master/tdm/tdm/backend/backend.py\", line 321, in _send_event_through_components_and_set_response\n    resulting_events = self._send_event_through_components(event)\n  File \"/home/amelieastbom/tdm-master/tdm/tdm/backend/backend.py\", line 334, in _send_event_through_components\n    moves = self._dm.act(events)\n  File \"/home/amelieastbom/tdm-master/tdm/tdm/dm/component.py\", line 46, in act\n    self._act_on_queued_events()\n  File \"/home/amelieastbom/tdm-master/tdm/tdm/dm/component.py\", line 86, in _act_on_queued_events\n    self._handle_event(event)\n  File \"/home/amelieastbom/tdm-master/tdm/tdm/dm/component.py\", line 101, in _handle_event\n    self.forward_event_internally_and_externally(event)\n  File \"/home/amelieastbom/tdm-master/tdm/tdm/dm/component.py\", line 104, in forward_event_internally_and_externally\n    self._event_dispatcher.dispatch(event)\n  File \"/home/amelieastbom/tdm-master/tdm/tdm/event_dispatcher.py\", line 27, in dispatch\n    self._send_event_to_subscribing_modules(event)\n  File \"/home/amelieastbom/tdm-master/tdm/tdm/event_dispatcher.py\", line 49, in _send_event_to_subscribing_modules\n    handler, event.get_type(), event)\n  File \"/home/amelieastbom/tdm-master/tdm/tdm/event_dispatcher.py\", line 55, in _send_to_subscribing_module\n    module.process_event(protected_event)\n  File \"/home/amelieastbom/tdm-master/tdm/tdm/dm/module.py\", line 50, in process_event\n    handler()\n  File \"/home/amelieastbom/tdm-master/tdm/tdm/dm/dme_module.py\", line 66, in _handle_interpretation\n    self._set_input_event_and_run_update_and_select()\n  File \"/home/amelieastbom/tdm-master/tdm/tdm/dm/dme_module.py\", line 71, in _set_input_event_and_run_update_and_select\n    self.run_update_and_set_ddd_when_needed()\n  File \"/home/amelieastbom/tdm-master/tdm/tdm/dm/dme_module.py\", line 76, in run_update_and_set_ddd_when_needed\n    self.run_update()\n  File \"/home/amelieastbom/tdm-master/tdm/tdm/dm/dme_module.py\", line 138, in run_update\n    self.update_module.run(self._tis)\n  File \"/home/amelieastbom/tdm-master/tdm/tdm/dm/update.py\", line 274, in run\n    RuleGroup.repeat_group_sequence(self.logger, [self._exec_plan_group, self._load_plan_group], tis)\n  File \"/home/amelieastbom/tdm-master/tdm/tdm/dm/isu_rule_group.py\", line 57, in repeat_group_sequence\n    if any(group._applicable_rules(tis)):\n  File \"/home/amelieastbom/tdm-master/tdm/tdm/dm/isu_rule_group.py\", line 34, in <genexpr>\n    return (rule for rule in self._rules if rule.is_applicable(tis))\n  File \"/home/amelieastbom/tdm-master/tdm/tdm/dm/isu_rule.py\", line 26, in is_applicable\n    return self.test_preconditions(self._ddd_component_manager, tis)\n  File \"/home/amelieastbom/tdm-master/tdm/tdm/dm/isu_rule.py\", line 31, in test_preconditions\n    return self.preconditions(ddd_component_manager, self.tis)\n  File \"/home/amelieastbom/tdm-master/tdm/tdm/dm/update_rules.py\", line 1715, in preconditions\n    for (question, result) in tis.get_resolving_results_from_services():\n  File \"/home/amelieastbom/tdm-master/tdm/tdm/dm/tis.py\", line 1441, in get_resolving_results_from_services\n    all_results = self.service_manager.query(question, self.session_id, self.shared.com, self.language_code)\n  File \"/home/amelieastbom/tdm-master/tdm/tdm/dm/service_manager.py\", line 202, in query\n    results = get_query_results_for_interface(ddd, interface)\n  File \"/home/amelieastbom/tdm-master/tdm/tdm/dm/service_manager.py\", line 185, in get_query_results_for_interface\n    return service_wrapper.query(question, parameters, min_results, max_results, session, context)\n  File \"/home/amelieastbom/tdm-master/tdm/tdm/ddd/services/http.py\", line 159, in query\n    headers={\"Content-type\": \"application/json\"})\n  File \"/home/amelieastbom/tdm-master/tdm/tdm/ddd/services/http.py\", line 38, in _post\n    raise HttpServiceInvocationException(str(exception))\ntdm.ddd.services.http.HttpServiceInvocationException: HTTPConnectionPool(host='127.0.0.1', port=10100): Max retries exceeded with url: /selected_alarm_time (Caused by NewConnectionError('<urllib3.connection.HTTPConnection object at 0x7f50c9bb9ed0>: Failed to establish a new connection: [Errno 111] Connection refused'))", "level": "error", "logger": "tdm", "time": "2020-09-17T13:51:31.596435Z"}
{"event": "RequestException encountered.", "exception": "Traceback (most recent call last):\n  File \"/home/amelieastbom/tdm-master/tdm/tdm/ddd/services/http.py\", line 34, in _post\n    self._validate_response(response)\n  File \"/home/amelieastbom/tdm-master/tdm/tdm/ddd/services/http.py\", line 61, in _validate_response\n    validate_http_status(response)\n  File \"/home/amelieastbom/tdm-master/tdm/tdm/ddd/services/http.py\", line 42, in validate_http_status\n    response.raise_for_status()\n  File \"/home/amelieastbom/tdmenvs/tdmenv/lib/python3.7/site-packages/requests/models.py\", line 940, in raise_for_status\n    raise HTTPError(http_error_msg, response=self)\nrequests.exceptions.HTTPError: 500 Server Error: INTERNAL SERVER ERROR for url: http://127.0.0.1:10100/selected_alarm_time", "level": "error", "logger": "tdm", "time": "2020-09-17T13:53:12.774596Z"}
{"event": "Encountered an error. Stopping and returning backend error.", "exception": "Traceback (most recent call last):\n  File \"/home/amelieastbom/tdm-master/tdm/tdm/ddd/services/http.py\", line 34, in _post\n    self._validate_response(response)\n  File \"/home/amelieastbom/tdm-master/tdm/tdm/ddd/services/http.py\", line 61, in _validate_response\n    validate_http_status(response)\n  File \"/home/amelieastbom/tdm-master/tdm/tdm/ddd/services/http.py\", line 42, in validate_http_status\n    response.raise_for_status()\n  File \"/home/amelieastbom/tdmenvs/tdmenv/lib/python3.7/site-packages/requests/models.py\", line 940, in raise_for_status\n    raise HTTPError(http_error_msg, response=self)\nrequests.exceptions.HTTPError: 500 Server Error: INTERNAL SERVER ERROR for url: http://127.0.0.1:10100/selected_alarm_time\n\nDuring handling of the above exception, another exception occurred:\n\nTraceback (most recent call last):\n  File \"/home/amelieastbom/tdm-master/tdm/tdm/backend/backend.py\", line 89, in handle_request_from_queue\n    self._handle_request(request)\n  File \"/home/amelieastbom/tdm-master/tdm/tdm/backend/backend.py\", line 115, in _handle_request\n    self._send_event_through_components_and_set_response(event)\n  File \"/home/amelieastbom/tdm-master/tdm/tdm/backend/backend.py\", line 321, in _send_event_through_components_and_set_response\n    resulting_events = self._send_event_through_components(event)\n  File \"/home/amelieastbom/tdm-master/tdm/tdm/backend/backend.py\", line 334, in _send_event_through_components\n    moves = self._dm.act(events)\n  File \"/home/amelieastbom/tdm-master/tdm/tdm/dm/component.py\", line 46, in act\n    self._act_on_queued_events()\n  File \"/home/amelieastbom/tdm-master/tdm/tdm/dm/component.py\", line 86, in _act_on_queued_events\n    self._handle_event(event)\n  File \"/home/amelieastbom/tdm-master/tdm/tdm/dm/component.py\", line 101, in _handle_event\n    self.forward_event_internally_and_externally(event)\n  File \"/home/amelieastbom/tdm-master/tdm/tdm/dm/component.py\", line 104, in forward_event_internally_and_externally\n    self._event_dispatcher.dispatch(event)\n  File \"/home/amelieastbom/tdm-master/tdm/tdm/event_dispatcher.py\", line 27, in dispatch\n    self._send_event_to_subscribing_modules(event)\n  File \"/home/amelieastbom/tdm-master/tdm/tdm/event_dispatcher.py\", line 49, in _send_event_to_subscribing_modules\n    handler, event.get_type(), event)\n  File \"/home/amelieastbom/tdm-master/tdm/tdm/event_dispatcher.py\", line 55, in _send_to_subscribing_module\n    module.process_event(protected_event)\n  File \"/home/amelieastbom/tdm-master/tdm/tdm/dm/module.py\", line 50, in process_event\n    handler()\n  File \"/home/amelieastbom/tdm-master/tdm/tdm/dm/dme_module.py\", line 66, in _handle_interpretation\n    self._set_input_event_and_run_update_and_select()\n  File \"/home/amelieastbom/tdm-master/tdm/tdm/dm/dme_module.py\", line 71, in _set_input_event_and_run_update_and_select\n    self.run_update_and_set_ddd_when_needed()\n  File \"/home/amelieastbom/tdm-master/tdm/tdm/dm/dme_module.py\", line 76, in run_update_and_set_ddd_when_needed\n    self.run_update()\n  File \"/home/amelieastbom/tdm-master/tdm/tdm/dm/dme_module.py\", line 138, in run_update\n    self.update_module.run(self._tis)\n  File \"/home/amelieastbom/tdm-master/tdm/tdm/dm/update.py\", line 274, in run\n    RuleGroup.repeat_group_sequence(self.logger, [self._exec_plan_group, self._load_plan_group], tis)\n  File \"/home/amelieastbom/tdm-master/tdm/tdm/dm/isu_rule_group.py\", line 57, in repeat_group_sequence\n    if any(group._applicable_rules(tis)):\n  File \"/home/amelieastbom/tdm-master/tdm/tdm/dm/isu_rule_group.py\", line 34, in <genexpr>\n    return (rule for rule in self._rules if rule.is_applicable(tis))\n  File \"/home/amelieastbom/tdm-master/tdm/tdm/dm/isu_rule.py\", line 26, in is_applicable\n    return self.test_preconditions(self._ddd_component_manager, tis)\n  File \"/home/amelieastbom/tdm-master/tdm/tdm/dm/isu_rule.py\", line 31, in test_preconditions\n    return self.preconditions(ddd_component_manager, self.tis)\n  File \"/home/amelieastbom/tdm-master/tdm/tdm/dm/update_rules.py\", line 1715, in preconditions\n    for (question, result) in tis.get_resolving_results_from_services():\n  File \"/home/amelieastbom/tdm-master/tdm/tdm/dm/tis.py\", line 1441, in get_resolving_results_from_services\n    all_results = self.service_manager.query(question, self.session_id, self.shared.com, self.language_code)\n  File \"/home/amelieastbom/tdm-master/tdm/tdm/dm/service_manager.py\", line 202, in query\n    results = get_query_results_for_interface(ddd, interface)\n  File \"/home/amelieastbom/tdm-master/tdm/tdm/dm/service_manager.py\", line 185, in get_query_results_for_interface\n    return service_wrapper.query(question, parameters, min_results, max_results, session, context)\n  File \"/home/amelieastbom/tdm-master/tdm/tdm/ddd/services/http.py\", line 159, in query\n    headers={\"Content-type\": \"application/json\"})\n  File \"/home/amelieastbom/tdm-master/tdm/tdm/ddd/services/http.py\", line 38, in _post\n    raise HttpServiceInvocationException(str(exception))\ntdm.ddd.services.http.HttpServiceInvocationException: 500 Server Error: INTERNAL SERVER ERROR for url: http://127.0.0.1:10100/selected_alarm_time", "level": "error", "logger": "tdm", "time": "2020-09-17T13:53:12.776134Z"}
{"event": "RequestException encountered.", "exception": "Traceback (most recent call last):\n  File \"/home/amelieastbom/tdm-master/tdm/tdm/ddd/services/http.py\", line 34, in _post\n    self._validate_response(response)\n  File \"/home/amelieastbom/tdm-master/tdm/tdm/ddd/services/http.py\", line 61, in _validate_response\n    validate_http_status(response)\n  File \"/home/amelieastbom/tdm-master/tdm/tdm/ddd/services/http.py\", line 42, in validate_http_status\n    response.raise_for_status()\n  File \"/home/amelieastbom/tdmenvs/tdmenv/lib/python3.7/site-packages/requests/models.py\", line 940, in raise_for_status\n    raise HTTPError(http_error_msg, response=self)\nrequests.exceptions.HTTPError: 500 Server Error: INTERNAL SERVER ERROR for url: http://127.0.0.1:10100/selected_alarm_time", "level": "error", "logger": "tdm", "time": "2020-09-17T13:53:13.031580Z"}
{"event": "Encountered an error. Stopping and returning backend error.", "exception": "Traceback (most recent call last):\n  File \"/home/amelieastbom/tdm-master/tdm/tdm/ddd/services/http.py\", line 34, in _post\n    self._validate_response(response)\n  File \"/home/amelieastbom/tdm-master/tdm/tdm/ddd/services/http.py\", line 61, in _validate_response\n    validate_http_status(response)\n  File \"/home/amelieastbom/tdm-master/tdm/tdm/ddd/services/http.py\", line 42, in validate_http_status\n    response.raise_for_status()\n  File \"/home/amelieastbom/tdmenvs/tdmenv/lib/python3.7/site-packages/requests/models.py\", line 940, in raise_for_status\n    raise HTTPError(http_error_msg, response=self)\nrequests.exceptions.HTTPError: 500 Server Error: INTERNAL SERVER ERROR for url: http://127.0.0.1:10100/selected_alarm_time\n\nDuring handling of the above exception, another exception occurred:\n\nTraceback (most recent call last):\n  File \"/home/amelieastbom/tdm-master/tdm/tdm/backend/backend.py\", line 89, in handle_request_from_queue\n    self._handle_request(request)\n  File \"/home/amelieastbom/tdm-master/tdm/tdm/backend/backend.py\", line 115, in _handle_request\n    self._send_event_through_components_and_set_response(event)\n  File \"/home/amelieastbom/tdm-master/tdm/tdm/backend/backend.py\", line 321, in _send_event_through_components_and_set_response\n    resulting_events = self._send_event_through_components(event)\n  File \"/home/amelieastbom/tdm-master/tdm/tdm/backend/backend.py\", line 334, in _send_event_through_components\n    moves = self._dm.act(events)\n  File \"/home/amelieastbom/tdm-master/tdm/tdm/dm/component.py\", line 46, in act\n    self._act_on_queued_events()\n  File \"/home/amelieastbom/tdm-master/tdm/tdm/dm/component.py\", line 86, in _act_on_queued_events\n    self._handle_event(event)\n  File \"/home/amelieastbom/tdm-master/tdm/tdm/dm/component.py\", line 101, in _handle_event\n    self.forward_event_internally_and_externally(event)\n  File \"/home/amelieastbom/tdm-master/tdm/tdm/dm/component.py\", line 104, in forward_event_internally_and_externally\n    self._event_dispatcher.dispatch(event)\n  File \"/home/amelieastbom/tdm-master/tdm/tdm/event_dispatcher.py\", line 27, in dispatch\n    self._send_event_to_subscribing_modules(event)\n  File \"/home/amelieastbom/tdm-master/tdm/tdm/event_dispatcher.py\", line 49, in _send_event_to_subscribing_modules\n    handler, event.get_type(), event)\n  File \"/home/amelieastbom/tdm-master/tdm/tdm/event_dispatcher.py\", line 55, in _send_to_subscribing_module\n    module.process_event(protected_event)\n  File \"/home/amelieastbom/tdm-master/tdm/tdm/dm/module.py\", line 50, in process_event\n    handler()\n  File \"/home/amelieastbom/tdm-master/tdm/tdm/dm/dme_module.py\", line 66, in _handle_interpretation\n    self._set_input_event_and_run_update_and_select()\n  File \"/home/amelieastbom/tdm-master/tdm/tdm/dm/dme_module.py\", line 71, in _set_input_event_and_run_update_and_select\n    self.run_update_and_set_ddd_when_needed()\n  File \"/home/amelieastbom/tdm-master/tdm/tdm/dm/dme_module.py\", line 76, in run_update_and_set_ddd_when_needed\n    self.run_update()\n  File \"/home/amelieastbom/tdm-master/tdm/tdm/dm/dme_module.py\", line 138, in run_update\n    self.update_module.run(self._tis)\n  File \"/home/amelieastbom/tdm-master/tdm/tdm/dm/update.py\", line 274, in run\n    RuleGroup.repeat_group_sequence(self.logger, [self._exec_plan_group, self._load_plan_group], tis)\n  File \"/home/amelieastbom/tdm-master/tdm/tdm/dm/isu_rule_group.py\", line 57, in repeat_group_sequence\n    if any(group._applicable_rules(tis)):\n  File \"/home/amelieastbom/tdm-master/tdm/tdm/dm/isu_rule_group.py\", line 34, in <genexpr>\n    return (rule for rule in self._rules if rule.is_applicable(tis))\n  File \"/home/amelieastbom/tdm-master/tdm/tdm/dm/isu_rule.py\", line 26, in is_applicable\n    return self.test_preconditions(self._ddd_component_manager, tis)\n  File \"/home/amelieastbom/tdm-master/tdm/tdm/dm/isu_rule.py\", line 31, in test_preconditions\n    return self.preconditions(ddd_component_manager, self.tis)\n  File \"/home/amelieastbom/tdm-master/tdm/tdm/dm/update_rules.py\", line 1715, in preconditions\n    for (question, result) in tis.get_resolving_results_from_services():\n  File \"/home/amelieastbom/tdm-master/tdm/tdm/dm/tis.py\", line 1441, in get_resolving_results_from_services\n    all_results = self.service_manager.query(question, self.session_id, self.shared.com, self.language_code)\n  File \"/home/amelieastbom/tdm-master/tdm/tdm/dm/service_manager.py\", line 202, in query\n    results = get_query_results_for_interface(ddd, interface)\n  File \"/home/amelieastbom/tdm-master/tdm/tdm/dm/service_manager.py\", line 185, in get_query_results_for_interface\n    return service_wrapper.query(question, parameters, min_results, max_results, session, context)\n  File \"/home/amelieastbom/tdm-master/tdm/tdm/ddd/services/http.py\", line 159, in query\n    headers={\"Content-type\": \"application/json\"})\n  File \"/home/amelieastbom/tdm-master/tdm/tdm/ddd/services/http.py\", line 38, in _post\n    raise HttpServiceInvocationException(str(exception))\ntdm.ddd.services.http.HttpServiceInvocationException: 500 Server Error: INTERNAL SERVER ERROR for url: http://127.0.0.1:10100/selected_alarm_time", "level": "error", "logger": "tdm", "time": "2020-09-17T13:53:13.032444Z"}
{"event": "RequestException encountered.", "exception": "Traceback (most recent call last):\n  File \"/home/amelieastbom/tdm-master/tdm/tdm/ddd/services/http.py\", line 34, in _post\n    self._validate_response(response)\n  File \"/home/amelieastbom/tdm-master/tdm/tdm/ddd/services/http.py\", line 61, in _validate_response\n    validate_http_status(response)\n  File \"/home/amelieastbom/tdm-master/tdm/tdm/ddd/services/http.py\", line 42, in validate_http_status\n    response.raise_for_status()\n  File \"/home/amelieastbom/tdmenvs/tdmenv/lib/python3.7/site-packages/requests/models.py\", line 940, in raise_for_status\n    raise HTTPError(http_error_msg, response=self)\nrequests.exceptions.HTTPError: 500 Server Error: INTERNAL SERVER ERROR for url: http://127.0.0.1:10100/selected_alarm_time", "level": "error", "logger": "tdm", "time": "2020-09-17T13:56:32.835520Z"}
{"event": "Encountered an error. Stopping and returning backend error.", "exception": "Traceback (most recent call last):\n  File \"/home/amelieastbom/tdm-master/tdm/tdm/ddd/services/http.py\", line 34, in _post\n    self._validate_response(response)\n  File \"/home/amelieastbom/tdm-master/tdm/tdm/ddd/services/http.py\", line 61, in _validate_response\n    validate_http_status(response)\n  File \"/home/amelieastbom/tdm-master/tdm/tdm/ddd/services/http.py\", line 42, in validate_http_status\n    response.raise_for_status()\n  File \"/home/amelieastbom/tdmenvs/tdmenv/lib/python3.7/site-packages/requests/models.py\", line 940, in raise_for_status\n    raise HTTPError(http_error_msg, response=self)\nrequests.exceptions.HTTPError: 500 Server Error: INTERNAL SERVER ERROR for url: http://127.0.0.1:10100/selected_alarm_time\n\nDuring handling of the above exception, another exception occurred:\n\nTraceback (most recent call last):\n  File \"/home/amelieastbom/tdm-master/tdm/tdm/backend/backend.py\", line 89, in handle_request_from_queue\n    self._handle_request(request)\n  File \"/home/amelieastbom/tdm-master/tdm/tdm/backend/backend.py\", line 115, in _handle_request\n    self._send_event_through_components_and_set_response(event)\n  File \"/home/amelieastbom/tdm-master/tdm/tdm/backend/backend.py\", line 321, in _send_event_through_components_and_set_response\n    resulting_events = self._send_event_through_components(event)\n  File \"/home/amelieastbom/tdm-master/tdm/tdm/backend/backend.py\", line 334, in _send_event_through_components\n    moves = self._dm.act(events)\n  File \"/home/amelieastbom/tdm-master/tdm/tdm/dm/component.py\", line 46, in act\n    self._act_on_queued_events()\n  File \"/home/amelieastbom/tdm-master/tdm/tdm/dm/component.py\", line 86, in _act_on_queued_events\n    self._handle_event(event)\n  File \"/home/amelieastbom/tdm-master/tdm/tdm/dm/component.py\", line 101, in _handle_event\n    self.forward_event_internally_and_externally(event)\n  File \"/home/amelieastbom/tdm-master/tdm/tdm/dm/component.py\", line 104, in forward_event_internally_and_externally\n    self._event_dispatcher.dispatch(event)\n  File \"/home/amelieastbom/tdm-master/tdm/tdm/event_dispatcher.py\", line 27, in dispatch\n    self._send_event_to_subscribing_modules(event)\n  File \"/home/amelieastbom/tdm-master/tdm/tdm/event_dispatcher.py\", line 49, in _send_event_to_subscribing_modules\n    handler, event.get_type(), event)\n  File \"/home/amelieastbom/tdm-master/tdm/tdm/event_dispatcher.py\", line 55, in _send_to_subscribing_module\n    module.process_event(protected_event)\n  File \"/home/amelieastbom/tdm-master/tdm/tdm/dm/module.py\", line 50, in process_event\n    handler()\n  File \"/home/amelieastbom/tdm-master/tdm/tdm/dm/dme_module.py\", line 66, in _handle_interpretation\n    self._set_input_event_and_run_update_and_select()\n  File \"/home/amelieastbom/tdm-master/tdm/tdm/dm/dme_module.py\", line 71, in _set_input_event_and_run_update_and_select\n    self.run_update_and_set_ddd_when_needed()\n  File \"/home/amelieastbom/tdm-master/tdm/tdm/dm/dme_module.py\", line 76, in run_update_and_set_ddd_when_needed\n    self.run_update()\n  File \"/home/amelieastbom/tdm-master/tdm/tdm/dm/dme_module.py\", line 138, in run_update\n    self.update_module.run(self._tis)\n  File \"/home/amelieastbom/tdm-master/tdm/tdm/dm/update.py\", line 274, in run\n    RuleGroup.repeat_group_sequence(self.logger, [self._exec_plan_group, self._load_plan_group], tis)\n  File \"/home/amelieastbom/tdm-master/tdm/tdm/dm/isu_rule_group.py\", line 57, in repeat_group_sequence\n    if any(group._applicable_rules(tis)):\n  File \"/home/amelieastbom/tdm-master/tdm/tdm/dm/isu_rule_group.py\", line 34, in <genexpr>\n    return (rule for rule in self._rules if rule.is_applicable(tis))\n  File \"/home/amelieastbom/tdm-master/tdm/tdm/dm/isu_rule.py\", line 26, in is_applicable\n    return self.test_preconditions(self._ddd_component_manager, tis)\n  File \"/home/amelieastbom/tdm-master/tdm/tdm/dm/isu_rule.py\", line 31, in test_preconditions\n    return self.preconditions(ddd_component_manager, self.tis)\n  File \"/home/amelieastbom/tdm-master/tdm/tdm/dm/update_rules.py\", line 1715, in preconditions\n    for (question, result) in tis.get_resolving_results_from_services():\n  File \"/home/amelieastbom/tdm-master/tdm/tdm/dm/tis.py\", line 1441, in get_resolving_results_from_services\n    all_results = self.service_manager.query(question, self.session_id, self.shared.com, self.language_code)\n  File \"/home/amelieastbom/tdm-master/tdm/tdm/dm/service_manager.py\", line 202, in query\n    results = get_query_results_for_interface(ddd, interface)\n  File \"/home/amelieastbom/tdm-master/tdm/tdm/dm/service_manager.py\", line 185, in get_query_results_for_interface\n    return service_wrapper.query(question, parameters, min_results, max_results, session, context)\n  File \"/home/amelieastbom/tdm-master/tdm/tdm/ddd/services/http.py\", line 159, in query\n    headers={\"Content-type\": \"application/json\"})\n  File \"/home/amelieastbom/tdm-master/tdm/tdm/ddd/services/http.py\", line 38, in _post\n    raise HttpServiceInvocationException(str(exception))\ntdm.ddd.services.http.HttpServiceInvocationException: 500 Server Error: INTERNAL SERVER ERROR for url: http://127.0.0.1:10100/selected_alarm_time", "level": "error", "logger": "tdm", "time": "2020-09-17T13:56:32.835873Z"}
